Workbook

Sheet Inputs
A1: Fernhill Commons: independent Excel check of the AVIANCRE multifamily engine
A2: Built only from inputs.md, rules.md and rent-roll.csv (fictional sample data). Blue = input from inputs.md; black = formula.
A4: Input | B4: Value | C4: Source
A5: Analysis start date | B5: 46327 | C5: inputs.md: analysis start
A6: Units | B6: 120 | C6: inputs.md: property
A7: Market rent growth (annual step each Nov) | B7: 0.03 | C7: inputs.md: revenue
A8: General vacancy (floor) | B8: 0.05 | C8: inputs.md: revenue
A9: Credit loss | B9: 0.01 | C9: inputs.md: revenue
A10: Operating expenses $/unit/yr (year 1) | B10: 6800 | C10: inputs.md: operating expenses
A11: Expense growth | B11: 0.03 | C11: inputs.md: operating expenses
A12: Management fee (% of EGI) | B12: 0.03 | C12: inputs.md: operating expenses
A13: Capital reserves $/unit/yr (flat) | B13: 300 | C13: inputs.md: capital
A14: Initial capex | B14: 0 | C14: inputs.md: capital
A15: Turnover share per roll | B15: 0.5 | C15: inputs.md: capital
A16: Turnover cost per move-out (year 1) | B16: 1000 | C16: inputs.md: capital
... A29: Discount rate (unlevered NPV) | B29: 0.08 | C29: inputs.md: returns

Sheet Returns
A1: Acquisition, debt, sale and returns
A4: Year-1 NOI | C4: =Annual!C16 -> 1311652.5
A5: Purchase price (Y1 NOI / market cap) | C5: =C4/Inputs!$B$19 -> 20986440
A6: Closing costs | C6: =Inputs!$B$20*C5 -> 314796.6
A7: Total cost | C7: =C5+C6+Inputs!$B$14 -> 21301237
A8: Loan (LTV x price) | C8: =Inputs!$B$22*C5 -> 12591864
A9: Loan fee | C9: =Inputs!$B$26*C8 -> 125918.64
A10: Equity | C10: =C7-C8+C9 -> 8835291.3
A11: Amortizing payment (months 25+) | C11: =-PMT(Inputs!$B$23/12,Inputs!$B$25*12,C8) -> 79589.147
A12: Loan payoff (balance after month 120) | C12: =INDEX(Monthly!$N$2:$N$133,Inputs!$B$21*12) -> 11163528
A13: Exit NOI (normalized year 11) | C13: =Annual!M36 -> 1778732.6
A14: Gross sale price | C14: =C13/Inputs!$B$27 -> 27365116
A15: Net sale proceeds | C15: =C14*(1-Inputs!$B$28) -> 26817814
A16: Going-in cap | C16: =C4/C5 -> 0.0625
A17: Debt yield | C17: =C4/C8 -> 0.10416667
A19: Year | C19: 0 | D19: 1 | E19: 2 | F19: 3 | G19: 4 | H19: 5 | I19: 6 | J19: 7 | K19: 8 | L19: 9 | M19: 10
A20: Unlevered cash flow | C20: =-C7 -> -21301237 | D20: =Annual!C19 -> 1220152.5 | E20: =Annual!D19 -> 1256174.3 | F20: =Annual!E19 -> 1302475.9 | G20: =Annual!F19 -> 1344407.4 | H20: =Annual!G19 -> 1386130 | I20: =Annual!H19 -> 1428793.9 | J20: =Annual!I19 -> 1472737.7 | K20: =Annual!J19 -> 1517999.8 | L20: =Annual!K19 -> 1564619.8 | M20: =Annual!L19+$C$15 -> 28430452
A21: Levered cash flow | C21: =-C10 -> -8835291.3 | D21: =Annual!C21 -> 401681.35 | E21: =Annual!D21 -> 437703.15 | F21: =Annual!E21 -> 347406.18 | G21: =Annual!F21 -> 389337.68 | H21: =Annual!G21 -> 431060.23 | I21: =Annual!H21 -> 473724.13 | J21: =Annual!I21 -> 517667.94 | K21: =Annual!J21 -> 562930.07 | L21: =Annual!K21 -> 609550.07 | M21: =Annual!L21+$C$15-$C$12 -> 16311854
A23: Unlevered IRR | C23: =IRR(C20:M20) -> 0.082560126
A24: Levered IRR | C24: =IRR(C21:M21) -> 0.10043024
A25: Unlevered NPV @ discount rate | C25: =C20+NPV(Inputs!$B$29,D20:M20) -> 402343.56
A26: Unlevered equity multiple | C26: =SUM(D20:M20)/C7 -> 1.9212004
A27: Levered equity multiple | C27: =SUM(D21:M21)/C10 -> 2.3183067
A28: Minimum DSCR (years 1-10) | C28: =MIN(Annual!C25:L25) -> 1.4680916
A29: Year-1 cash-on-cash | C29: =Annual!C26 -> 0.045463282

Sheet Annual
A1: Annual cash flow ($)
A3: Analysis year | C3: 1 | D3: 2 | E3: 3 | F3: 4 | G3: 5 | H3: 6 | I3: 7 | J3: 8 | K3: 9 | L3: 10 | M3: 11
A4: Gross potential rent | C4: =SUMIF(Monthly!$B$2:$B$133,1,Monthly!$C$2:$C$133) -> 2333160 | D4: =SUMIF(Monthly!$B$2:$B$133,2,Monthly!$C$2:$C$133) -> 2403154.8 | E4: =SUMIF(Monthly!$B$2:$B$133,3,Monthly!$C$2:$C$133) -> 2475249.4 | F4: =SUMIF(Monthly!$B$2:$B$133,4,Monthly!$C$2:$C$133) -> 2549506.9 | G4: =SUMIF(Monthly!$B$2:$B$133,5,Monthly!$C$2:$C$133) -> 2625992.1 | H4: =SUMIF(Monthly!$B$2:$B$133,6,Monthly!$C$2:$C$133) -> 2704771.9 | I4: =SUMIF(Monthly!$B$2:$B$133,7,Monthly!$C$2:$C$133) -> 2785915.1 | J4: =SUMIF(Monthly!$B$2:$B$133,8,Monthly!$C$2:$C$133) -> 2869492.5 | K4: =SUMIF(Monthly!$B$2:$B$133,9,Monthly!$C$2:$C$133) -> 2955577.3 | L4: =SUMIF(Monthly!$B$2:$B$133,10,Monthly!$C$2:$C$133) -> 3044244.6 | M4: =SUMIF(Monthly!$B$2:$B$133,11,Monthly!$C$2:$C$133) -> 3135571.9
A5: Less: loss to lease | C5: =SUMIF(Monthly!$B$2:$B$133,1,Monthly!$F$2:$F$133) -> 40080.5 | D5: =SUMIF(Monthly!$B$2:$B$133,2,Monthly!$F$2:$F$133) -> 38024.912 | E5: =SUMIF(Monthly!$B$2:$B$133,3,Monthly!$F$2:$F$133) -> 30904.654 | F5: =SUMIF(Monthly!$B$2:$B$133,4,Monthly!$F$2:$F$133) -> 29883.693 | G5: =SUMIF(Monthly!$B$2:$B$133,5,Monthly!$F$2:$F$133) -> 30440.041 | H5: =SUMIF(Monthly!$B$2:$B$133,6,Monthly!$F$2:$F$133) -> 31353.243 | I5: =SUMIF(Monthly!$B$2:$B$133,7,Monthly!$F$2:$F$133) -> 32293.84 | J5: =SUMIF(Monthly!$B$2:$B$133,8,Monthly!$F$2:$F$133) -> 33262.655 | K5: =SUMIF(Monthly!$B$2:$B$133,9,Monthly!$F$2:$F$133) -> 34260.535 | L5: =SUMIF(Monthly!$B$2:$B$133,10,Monthly!$F$2:$F$133) -> 35288.351 | M5: =SUMIF(Monthly!$B$2:$B$133,11,Monthly!$F$2:$F$133) -> 36347.001
A6: Other income | C6: =Units!$G$123*12*(1+Inputs!$B$7)^(1-1) -> 39144 | D6: =Units!$G$123*12*(1+Inputs!$B$7)^(2-1) -> 40318.32 | E6: =Units!$G$123*12*(1+Inputs!$B$7)^(3-1) -> 41527.87 | F6: =Units!$G$123*12*(1+Inputs!$B$7)^(4-1) -> 42773.706 | G6: =Units!$G$123*12*(1+Inputs!$B$7)^(5-1) -> 44056.917 | H6: =Units!$G$123*12*(1+Inputs!$B$7)^(6-1) -> 45378.624 | I6: =Units!$G$123*12*(1+Inputs!$B$7)^(7-1) -> 46739.983 | J6: =Units!$G$123*12*(1+Inputs!$B$7)^(8-1) -> 48142.183 | K6: =Units!$G$123*12*(1+Inputs!$B$7)^(9-1) -> 49586.448 | L6: =Units!$G$123*12*(1+Inputs!$B$7)^(10-1) -> 51074.042 | M6: =Units!$G$123*12*(1+Inputs!$B$7)^(11-1) -> 52606.263
A7: Potential gross income | C7: =C4-C5+C6 -> 2332223.5 | D7: =D4-D5+D6 -> 2405448.2 | E7: =E4-E5+E6 -> 2485872.7 | F7: =F4-F5+F6 -> 2562396.9 | G7: =G4-G5+G6 -> 2639609 | H7: =H4-H5+H6 -> 2718797.3 | I7: =I4-I5+I6 -> 2800361.2 | J7: =J4-J5+J6 -> 2884372 | ... M7: =M4-M5+M6 -> 3151831.2
A8: Less: absorption vacancy | C8: =SUMIF(Monthly!$B$2:$B$133,1,Monthly!$G$2:$G$133) -> 3375 | D8: =SUMIF(Monthly!$B$2:$B$133,2,Monthly!$G$2:$G$133) -> 0 | E8: =SUMIF(Monthly!$B$2:$B$133,3,Monthly!$G$2:$G$133) -> 0 | F8: =SUMIF(Monthly!$B$2:$B$133,4,Monthly!$G$2:$G$133) -> 0 | G8: =SUMIF(Monthly!$B$2:$B$133,5,Monthly!$G$2:$G$133) -> 0 | H8: =SUMIF(Monthly!$B$2:$B$133,6,Monthly!$G$2:$G$133) -> 0 | I8: =SUMIF(Monthly!$B$2:$B$133,7,Monthly!$G$2:$G$133) -> 0 | J8: =SUMIF(Monthly!$B$2:$B$133,8,Monthly!$G$2:$G$133) -> 0 | K8: =SUMIF(Monthly!$B$2:$B$133,9,Monthly!$G$2:$G$133) -> 0 | L8: =SUMIF(Monthly!$B$2:$B$133,10,Monthly!$G$2:$G$133) -> 0 | M8: =SUMIF(Monthly!$B$2:$B$133,11,Monthly!$G$2:$G$133) -> 0
A9: Less: general vacancy (floor) | C9: =MAX(0,Inputs!$B$8*C7-C8) -> 113236.18 | D9: =MAX(0,Inputs!$B$8*D7-D8) -> 120272.41 | E9: =MAX(0,Inputs!$B$8*E7-E8) -> 124293.63 | F9: =MAX(0,Inputs!$B$8*F7-F8) -> 128119.85 | G9: =MAX(0,Inputs!$B$8*G7-G8) -> 131980.45 | H9: =MAX(0,Inputs!$B$8*H7-H8) -> 135939.86 | I9: =MAX(0,Inputs!$B$8*I7-I8) -> 140018.06 | J9: =MAX(0,Inputs!$B$8*J7-J8) -> 144218.6 | ... M9: =MAX(0,Inputs!$B$8*M7-M8) -> 157591.56
A10: Income before credit loss | C10: =C7-C8-C9 -> 2215612.3 | D10: =D7-D8-D9 -> 2285175.8 | E10: =E7-E8-E9 -> 2361579 | F10: =F7-F8-F9 -> 2434277.1 | G10: =G7-G8-G9 -> 2507628.6 | H10: =H7-H8-H9 -> 2582857.4 | I10: =I7-I8-I9 -> 2660343.1 | J10: =J7-J8-J9 -> 2740153.4 | ... M10: =M7-M8-M9 -> 2994239.6
A11: Less: credit loss | C11: =Inputs!$B$9*C10 -> 22156.123 | D11: =Inputs!$B$9*D10 -> 22851.758 | E11: =Inputs!$B$9*E10 -> 23615.79 | F11: =Inputs!$B$9*F10 -> 24342.771 | G11: =Inputs!$B$9*G10 -> 25076.286 | H11: =Inputs!$B$9*H10 -> 25828.574 | I11: =Inputs!$B$9*I10 -> 26603.431 | J11: =Inputs!$B$9*J10 -> 27401.534 | ... M11: =Inputs!$B$9*M10 -> 29942.396
A12: Effective gross income | C12: =C10-C11 -> 2193456.2 | D12: =D10-D11 -> 2262324 | E12: =E10-E11 -> 2337963.2 | F12: =F10-F11 -> 2409934.3 | G12: =G10-G11 -> 2482552.3 | H12: =H10-H11 -> 2557028.8 | I12: =I10-I11 -> 2633739.7 | J12: =J10-J11 -> 2712751.9 | ... M12: =M10-M11 -> 2964297.2
A13: Operating expenses | C13: =Inputs!$B$10*Inputs!$B$6*(1+Inputs!$B$11)^(1-1) -> 816000 | D13: =Inputs!$B$10*Inputs!$B$6*(1+Inputs!$B$11)^(2-1) -> 840480 | E13: =Inputs!$B$10*Inputs!$B$6*(1+Inputs!$B$11)^(3-1) -> 865694.4 | F13: =Inputs!$B$10*Inputs!$B$6*(1+Inputs!$B$11)^(4-1) -> 891665.23 | G13: =Inputs!$B$10*Inputs!$B$6*(1+Inputs!$B$11)^(5-1) -> 918415.19 | H13: =Inputs!$B$10*Inputs!$B$6*(1+Inputs!$B$11)^(6-1) -> 945967.64 | I13: =Inputs!$B$10*Inputs!$B$6*(1+Inputs!$B$11)^(7-1) -> 974346.67 | J13: =Inputs!$B$10*Inputs!$B$6*(1+Inputs!$B$11)^(8-1) -> 1003577.1 | K13: =Inputs!$B$10*Inputs!$B$6*(1+Inputs!$B$11)^(9-1) -> 1033684.4 | L13: =Inputs!$B$10*Inputs!$B$6*(1+Inputs!$B$11)^(10-1) -> 1064694.9 | M13: =Inputs!$B$10*Inputs!$B$6*(1+Inputs!$B$11)^(11-1) -> 1096635.8
A14: Management fee | C14: =Inputs!$B$12*C12 -> 65803.686 | D14: =Inputs!$B$12*D12 -> 67869.721 | E14: =Inputs!$B$12*E12 -> 70138.897 | F14: =Inputs!$B$12*F12 -> 72298.03 | G14: =Inputs!$B$12*G12 -> 74476.568 | H14: =Inputs!$B$12*H12 -> 76710.865 | I14: =Inputs!$B$12*I12 -> 79012.191 | J14: =Inputs!$B$12*J12 -> 81382.557 | ... M14: =Inputs!$B$12*M12 -> 88928.917
A15: Total operating expenses | C15: =C13+C14 -> 881803.69 | D15: =D13+D14 -> 908349.72 | E15: =E13+E14 -> 935833.3 | F15: =F13+F14 -> 963963.26 | G15: =G13+G14 -> 992891.76 | H15: =H13+H14 -> 1022678.5 | I15: =I13+I14 -> 1053358.9 | J15: =J13+J14 -> 1084959.6 | ... M15: =M13+M14 -> 1185564.7
A16: Net operating income | C16: =C12-C15 -> 1311652.5 | D16: =D12-D15 -> 1353974.3 | E16: =E12-E15 -> 1402129.9 | F16: =F12-F15 -> 1445971.1 | G16: =G12-G15 -> 1489660.5 | H16: =H12-H15 -> 1534350.3 | I16: =I12-I15 -> 1580380.8 | J16: =J12-J15 -> 1627792.3 | ... M16: =M12-M15 -> 1778732.6
A17: Turnover cost | C17: =SUMIF(Monthly!$B$2:$B$133,1,Monthly!$I$2:$I$133) -> 55500 | D17: =SUMIF(Monthly!$B$2:$B$133,2,Monthly!$I$2:$I$133) -> 61800 | E17: =SUMIF(Monthly!$B$2:$B$133,3,Monthly!$I$2:$I$133) -> 63654 | F17: =SUMIF(Monthly!$B$2:$B$133,4,Monthly!$I$2:$I$133) -> 65563.62 | G17: =SUMIF(Monthly!$B$2:$B$133,5,Monthly!$I$2:$I$133) -> 67530.529 | H17: =SUMIF(Monthly!$B$2:$B$133,6,Monthly!$I$2:$I$133) -> 69556.444 | I17: =SUMIF(Monthly!$B$2:$B$133,7,Monthly!$I$2:$I$133) -> 71643.138 | J17: =SUMIF(Monthly!$B$2:$B$133,8,Monthly!$I$2:$I$133) -> 73792.432 | K17: =SUMIF(Monthly!$B$2:$B$133,9,Monthly!$I$2:$I$133) -> 76006.205 | L17: =SUMIF(Monthly!$B$2:$B$133,10,Monthly!$I$2:$I$133) -> 78286.391 | M17: =SUMIF(Monthly!$B$2:$B$133,11,Monthly!$I$2:$I$133) -> 80634.983
A18: Capital reserves | C18: =Inputs!$B$13*Inputs!$B$6 -> 36000 | D18: =Inputs!$B$13*Inputs!$B$6 -> 36000 | E18: =Inputs!$B$13*Inputs!$B$6 -> 36000 | F18: =Inputs!$B$13*Inputs!$B$6 -> 36000 | G18: =Inputs!$B$13*Inputs!$B$6 -> 36000 | H18: =Inputs!$B$13*Inputs!$B$6 -> 36000 | I18: =Inputs!$B$13*Inputs!$B$6 -> 36000 | J18: =Inputs!$B$13*Inputs!$B$6 -> 36000 | ... M18: =Inputs!$B$13*Inputs!$B$6 -> 36000
A19: Cash flow before debt | C19: =C16-C17-C18 -> 1220152.5 | D19: =D16-D17-D18 -> 1256174.3 | E19: =E16-E17-E18 -> 1302475.9 | F19: =F16-F17-F18 -> 1344407.4 | G19: =G16-G17-G18 -> 1386130 | H19: =H16-H17-H18 -> 1428793.9 | I19: =I16-I17-I18 -> 1472737.7 | J19: =J16-J17-J18 -> 1517999.8 | ... M19: =M16-M17-M18 -> 1662097.6
A20: Debt service | C20: =SUMIF(Monthly!$B$2:$B$133,1,Monthly!$K$2:$K$133) -> 818471.17 | D20: =SUMIF(Monthly!$B$2:$B$133,2,Monthly!$K$2:$K$133) -> 818471.17 | E20: =SUMIF(Monthly!$B$2:$B$133,3,Monthly!$K$2:$K$133) -> 955069.76 | F20: =SUMIF(Monthly!$B$2:$B$133,4,Monthly!$K$2:$K$133) -> 955069.76 | G20: =SUMIF(Monthly!$B$2:$B$133,5,Monthly!$K$2:$K$133) -> 955069.76 | H20: =SUMIF(Monthly!$B$2:$B$133,6,Monthly!$K$2:$K$133) -> 955069.76 | I20: =SUMIF(Monthly!$B$2:$B$133,7,Monthly!$K$2:$K$133) -> 955069.76 | J20: =SUMIF(Monthly!$B$2:$B$133,8,Monthly!$K$2:$K$133) -> 955069.76 | K20: =SUMIF(Monthly!$B$2:$B$133,9,Monthly!$K$2:$K$133) -> 955069.76 | L20: =SUMIF(Monthly!$B$2:$B$133,10,Monthly!$K$2:$K$133) -> 955069.76 | M20: =SUMIF(Monthly!$B$2:$B$133,11,Monthly!$K$2:$K$133) -> 0
A21: Cash flow after debt | C21: =C19-C20 -> 401681.35 | D21: =D19-D20 -> 437703.15 | E21: =E19-E20 -> 347406.18 | F21: =F19-F20 -> 389337.68 | G21: =G19-G20 -> 431060.23 | H21: =H19-H20 -> 473724.13 | I21: =I19-I20 -> 517667.94 | J21: =J19-J20 -> 562930.07 | ... M21: =M19-M20 -> 1662097.6
A23: Occupied unit-months | C23: =SUMIF(Monthly!$B$2:$B$133,1,Monthly!$H$2:$H$133) -> 1438 | D23: =SUMIF(Monthly!$B$2:$B$133,2,Monthly!$H$2:$H$133) -> 1440 | E23: =SUMIF(Monthly!$B$2:$B$133,3,Monthly!$H$2:$H$133) -> 1440 | F23: =SUMIF(Monthly!$B$2:$B$133,4,Monthly!$H$2:$H$133) -> 1440 | G23: =SUMIF(Monthly!$B$2:$B$133,5,Monthly!$H$2:$H$133) -> 1440 | H23: =SUMIF(Monthly!$B$2:$B$133,6,Monthly!$H$2:$H$133) -> 1440 | I23: =SUMIF(Monthly!$B$2:$B$133,7,Monthly!$H$2:$H$133) -> 1440 | J23: =SUMIF(Monthly!$B$2:$B$133,8,Monthly!$H$2:$H$133) -> 1440 | K23: =SUMIF(Monthly!$B$2:$B$133,9,Monthly!$H$2:$H$133) -> 1440 | L23: =SUMIF(Monthly!$B$2:$B$133,10,Monthly!$H$2:$H$133) -> 1440 | M23: =SUMIF(Monthly!$B$2:$B$133,11,Monthly!$H$2:$H$133) -> 1440
A24: Physical occupancy | C24: =C23/(Inputs!$B$6*12) -> 0.99861111 | D24: =D23/(Inputs!$B$6*12) -> 1 | E24: =E23/(Inputs!$B$6*12) -> 1 | F24: =F23/(Inputs!$B$6*12) -> 1 | G24: =G23/(Inputs!$B$6*12) -> 1 | H24: =H23/(Inputs!$B$6*12) -> 1 | I24: =I23/(Inputs!$B$6*12) -> 1 | J24: =J23/(Inputs!$B$6*12) -> 1 | ... M24: =M23/(Inputs!$B$6*12) -> 1
A25: DSCR | C25: =IF(C20=0,"",C16/C20) -> 1.6025641 | D25: =IF(D20=0,"",D16/D20) -> 1.6542725 | E25: =IF(E20=0,"",E16/E20) -> 1.4680916 | F25: =IF(F20=0,"",F16/F20) -> 1.5139952 | G25: =IF(G20=0,"",G16/G20) -> 1.55974 | H25: =IF(H20=0,"",H16/H20) -> 1.6065322 | I25: =IF(I20=0,"",I16/I20) -> 1.6547282 | J25: =IF(J20=0,"",J16/J20) -> 1.70437 | ... M25: =IF(M20=0,"",M16/M20)
A26: Cash-on-cash | C26: =C21/Returns!$C$10 -> 0.045463282 | D26: =D21/Returns!$C$10 -> 0.049540319 | E26: =E21/Returns!$C$10 -> 0.039320285 | F26: =F21/Returns!$C$10 -> 0.044066196 | G26: =G21/Returns!$C$10 -> 0.048788456 | H26: =H21/Returns!$C$10 -> 0.053617261 | I26: =I21/Returns!$C$10 -> 0.058590931 | J26: =J21/Returns!$C$10 -> 0.06371381 | ... M26: =M21/Returns!$C$10 -> 0.18812029
A28: Year 11 normalized for exit (absorption vacancy removed, full 5% general vacancy)
A29: Potential gross income | M29: =M7 -> 3151831.2
A30: General vacancy (full) | M30: =Inputs!$B$8*M29 -> 157591.56
A31: Income before credit loss | M31: =M29-M30 -> 2994239.6
A32: Credit loss | M32: =Inputs!$B$9*M31 -> 29942.396
A33: Effective gross income | M33: =M31-M32 -> 2964297.2
A34: Operating expenses | M34: =M13 -> 1096635.8
A35: Management fee | M35: =Inputs!$B$12*M33 -> 88928.917
A36: Normalized year-11 NOI | M36: =M33-M34-M35 -> 1778732.6
A37: Note: rows 20, 21, 25, 26 are blank in year 11 (sale after month 120).

Sheet Units
A1: Unit | B1: Floor plan | C1: SF | D1: Status | E1: Market rent $/mo | F1: In-place rent $/mo | G1: Other income $/mo | H1: Lease end | I1: Pre-leased | J1: Future lease rent | K1: Occupied (1/0) | L1: On notice w/ signed resident | M1: First roll month (occupied) | N1: Lease-up queue position | O1: Lease-up start month | P1: Leased from month | Q1: First regular roll month | R1: Rent at lease-up start
A2: 101 | B2: 735 SF | C2: 735 | D2: Occupied | E2: 1525 | F2: 1565 | G2: 0 | H2: 46356 | K2: =IF(D2="Occupied",1,0) -> 1 | L2: =IF(AND(K2=1,I2="Yes"),1,0) -> 0 | M2: =IF(K2=1,IF(OR(H2="",H2<Inputs!$B$5),1,(YEAR(H2)-YEAR(Inputs!$B$5))*12+MONTH(H2)-MONTH(Inputs!$B$5)+2),"") -> 2 | N2: =IF(K2=0,IF(I2="Yes",COUNTIFS(K$2:K2,0,I$2:I2,"Yes")-1,COUNTIFS(K$2:K$121,0,I$2:I$121,"Yes")+COUNTIFS(K$2:K2,0,I$2:I2,"<>Yes")-1),"") | O2: =IF(K2=0,INT(N2/Inputs!$B$17)+1,"") | P2: =IF(K2=1,1,O2) -> 1 | Q2: =IF(K2=1,M2,O2+12) -> 2 | R2: =IF(K2=0,IF(AND(I2="Yes",J2<>""),J2,E2*(1+Inputs!$B$7)^(INT((O2-1)/12))),"")
A3: 102 | B3: 735 SF | C3: 735 | D3: Occupied | E3: 1525 | F3: 1235 | G3: 45 | H3: 46477 | K3: =IF(D3="Occupied",1,0) -> 1 | L3: =IF(AND(K3=1,I3="Yes"),1,0) -> 0 | M3: =IF(K3=1,IF(OR(H3="",H3<Inputs!$B$5),1,(YEAR(H3)-YEAR(Inputs!$B$5))*12+MONTH(H3)-MONTH(Inputs!$B$5)+2),"") -> 6 | N3: =IF(K3=0,IF(I3="Yes",COUNTIFS(K$2:K3,0,I$2:I3,"Yes")-1,COUNTIFS(K$2:K$121,0,I$2:I$121,"Yes")+COUNTIFS(K$2:K3,0,I$2:I3,"<>Yes")-1),"") | O3: =IF(K3=0,INT(N3/Inputs!$B$17)+1,"") | P3: =IF(K3=1,1,O3) -> 1 | Q3: =IF(K3=1,M3,O3+12) -> 6 | R3: =IF(K3=0,IF(AND(I3="Yes",J3<>""),J3,E3*(1+Inputs!$B$7)^(INT((O3-1)/12))),"")
A4: 103 | B4: 735 SF | C4: 735 | D4: Occupied | E4: 1525 | F4: 1475 | G4: 62 | H4: 46630 | K4: =IF(D4="Occupied",1,0) -> 1 | L4: =IF(AND(K4=1,I4="Yes"),1,0) -> 0 | M4: =IF(K4=1,IF(OR(H4="",H4<Inputs!$B$5),1,(YEAR(H4)-YEAR(Inputs!$B$5))*12+MONTH(H4)-MONTH(Inputs!$B$5)+2),"") -> 11 | N4: =IF(K4=0,IF(I4="Yes",COUNTIFS(K$2:K4,0,I$2:I4,"Yes")-1,COUNTIFS(K$2:K$121,0,I$2:I$121,"Yes")+COUNTIFS(K$2:K4,0,I$2:I4,"<>Yes")-1),"") | O4: =IF(K4=0,INT(N4/Inputs!$B$17)+1,"") | P4: =IF(K4=1,1,O4) -> 1 | Q4: =IF(K4=1,M4,O4+12) -> 11 | R4: =IF(K4=0,IF(AND(I4="Yes",J4<>""),J4,E4*(1+Inputs!$B$7)^(INT((O4-1)/12))),"")
A5: 104 | B5: 735 SF | C5: 735 | D5: Vacant | E5: 1525 | F5: 0 | G5: 0 | K5: =IF(D5="Occupied",1,0) -> 0 | L5: =IF(AND(K5=1,I5="Yes"),1,0) -> 0 | M5: =IF(K5=1,IF(OR(H5="",H5<Inputs!$B$5),1,(YEAR(H5)-YEAR(Inputs!$B$5))*12+MONTH(H5)-MONTH(Inputs!$B$5)+2),"") | N5: =IF(K5=0,IF(I5="Yes",COUNTIFS(K$2:K5,0,I$2:I5,"Yes")-1,COUNTIFS(K$2:K$121,0,I$2:I$121,"Yes")+COUNTIFS(K$2:K5,0,I$2:I5,"<>Yes")-1),"") -> 3 | O5: =IF(K5=0,INT(N5/Inputs!$B$17)+1,"") -> 1 | P5: =IF(K5=1,1,O5) -> 1 | Q5: =IF(K5=1,M5,O5+12) -> 13 | R5: =IF(K5=0,IF(AND(I5="Yes",J5<>""),J5,E5*(1+Inputs!$B$7)^(INT((O5-1)/12))),"") -> 1525
A6: 105 | B6: 735 SF | C6: 735 | D6: Occupied | E6: 1525 | F6: 1445 | G6: 0 | H6: 46387 | K6: =IF(D6="Occupied",1,0) -> 1 | L6: =IF(AND(K6=1,I6="Yes"),1,0) -> 0 | M6: =IF(K6=1,IF(OR(H6="",H6<Inputs!$B$5),1,(YEAR(H6)-YEAR(Inputs!$B$5))*12+MONTH(H6)-MONTH(Inputs!$B$5)+2),"") -> 3 | N6: =IF(K6=0,IF(I6="Yes",COUNTIFS(K$2:K6,0,I$2:I6,"Yes")-1,COUNTIFS(K$2:K$121,0,I$2:I$121,"Yes")+COUNTIFS(K$2:K6,0,I$2:I6,"<>Yes")-1),"") | O6: =IF(K6=0,INT(N6/Inputs!$B$17)+1,"") | P6: =IF(K6=1,1,O6) -> 1 | Q6: =IF(K6=1,M6,O6+12) -> 3 | R6: =IF(K6=0,IF(AND(I6="Yes",J6<>""),J6,E6*(1+Inputs!$B$7)^(INT((O6-1)/12))),"")
A7: 106 | B7: 735 SF | C7: 735 | D7: Occupied | E7: 1525 | F7: 1400 | G7: 52 | H7: 46418 | K7: =IF(D7="Occupied",1,0) -> 1 | L7: =IF(AND(K7=1,I7="Yes"),1,0) -> 0 | M7: =IF(K7=1,IF(OR(H7="",H7<Inputs!$B$5),1,(YEAR(H7)-YEAR(Inputs!$B$5))*12+MONTH(H7)-MONTH(Inputs!$B$5)+2),"") -> 4 | N7: =IF(K7=0,IF(I7="Yes",COUNTIFS(K$2:K7,0,I$2:I7,"Yes")-1,COUNTIFS(K$2:K$121,0,I$2:I$121,"Yes")+COUNTIFS(K$2:K7,0,I$2:I7,"<>Yes")-1),"") | O7: =IF(K7=0,INT(N7/Inputs!$B$17)+1,"") | P7: =IF(K7=1,1,O7) -> 1 | Q7: =IF(K7=1,M7,O7+12) -> 4 | R7: =IF(K7=0,IF(AND(I7="Yes",J7<>""),J7,E7*(1+Inputs!$B$7)^(INT((O7-1)/12))),"")
A8: 107 | B8: 735 SF | C8: 735 | D8: Occupied | E8: 1525 | F8: 1580 | G8: 45 | H8: 46387 | K8: =IF(D8="Occupied",1,0) -> 1 | L8: =IF(AND(K8=1,I8="Yes"),1,0) -> 0 | M8: =IF(K8=1,IF(OR(H8="",H8<Inputs!$B$5),1,(YEAR(H8)-YEAR(Inputs!$B$5))*12+MONTH(H8)-MONTH(Inputs!$B$5)+2),"") -> 3 | N8: =IF(K8=0,IF(I8="Yes",COUNTIFS(K$2:K8,0,I$2:I8,"Yes")-1,COUNTIFS(K$2:K$121,0,I$2:I$121,"Yes")+COUNTIFS(K$2:K8,0,I$2:I8,"<>Yes")-1),"") | O8: =IF(K8=0,INT(N8/Inputs!$B$17)+1,"") | P8: =IF(K8=1,1,O8) -> 1 | Q8: =IF(K8=1,M8,O8+12) -> 3 | R8: =IF(K8=0,IF(AND(I8="Yes",J8<>""),J8,E8*(1+Inputs!$B$7)^(INT((O8-1)/12))),"")
A9: 108 | B9: 735 SF | C9: 735 | D9: Occupied | E9: 1525 | F9: 1475 | G9: 0 | H9: 46538 | K9: =IF(D9="Occupied",1,0) -> 1 | L9: =IF(AND(K9=1,I9="Yes"),1,0) -> 0 | M9: =IF(K9=1,IF(OR(H9="",H9<Inputs!$B$5),1,(YEAR(H9)-YEAR(Inputs!$B$5))*12+MONTH(H9)-MONTH(Inputs!$B$5)+2),"") -> 8 | N9: =IF(K9=0,IF(I9="Yes",COUNTIFS(K$2:K9,0,I$2:I9,"Yes")-1,COUNTIFS(K$2:K$121,0,I$2:I$121,"Yes")+COUNTIFS(K$2:K9,0,I$2:I9,"<>Yes")-1),"") | O9: =IF(K9=0,INT(N9/Inputs!$B$17)+1,"") | P9: =IF(K9=1,1,O9) -> 1 | Q9: =IF(K9=1,M9,O9+12) -> 8 | R9: =IF(K9=0,IF(AND(I9="Yes",J9<>""),J9,E9*(1+Inputs!$B$7)^(INT((O9-1)/12))),"")
A10: 109 | B10: 735 SF | C10: 735 | D10: Occupied | E10: 1525 | F10: 1565 | G10: 12 | H10: 46568 | K10: =IF(D10="Occupied",1,0) -> 1 | L10: =IF(AND(K10=1,I10="Yes"),1,0) -> 0 | M10: =IF(K10=1,IF(OR(H10="",H10<Inputs!$B$5),1,(YEAR(H10)-YEAR(Inputs!$B$5))*12+MONTH(H10)-MONTH(Inputs!$B$5)+2),"") -> 9 | N10: =IF(K10=0,IF(I10="Yes",COUNTIFS(K$2:K10,0,I$2:I10,"Yes")-1,COUNTIFS(K$2:K$121,0,I$2:I$121,"Yes")+COUNTIFS(K$2:K10,0,I$2:I10,"<>Yes")-1),"") | O10: =IF(K10=0,INT(N10/Inputs!$B$17)+1,"") | P10: =IF(K10=1,1,O10) -> 1 | Q10: =IF(K10=1,M10,O10+12) -> 9 | R10: =IF(K10=0,IF(AND(I10="Yes",J10<>""),J10,E10*(1+Inputs!$B$7)^(INT((O10-1)/12))),"")
A11: 110 | B11: 735 SF | C11: 735 | D11: Occupied | E11: 1525 | F11: 1500 | G11: 37 | H11: 46660 | K11: =IF(D11="Occupied",1,0) -> 1 | L11: =IF(AND(K11=1,I11="Yes"),1,0) -> 0 | M11: =IF(K11=1,IF(OR(H11="",H11<Inputs!$B$5),1,(YEAR(H11)-YEAR(Inputs!$B$5))*12+MONTH(H11)-MONTH(Inputs!$B$5)+2),"") -> 12 | N11: =IF(K11=0,IF(I11="Yes",COUNTIFS(K$2:K11,0,I$2:I11,"Yes")-1,COUNTIFS(K$2:K$121,0,I$2:I$121,"Yes")+COUNTIFS(K$2:K11,0,I$2:I11,"<>Yes")-1),"") | O11: =IF(K11=0,INT(N11/Inputs!$B$17)+1,"") | P11: =IF(K11=1,1,O11) -> 1 | Q11: =IF(K11=1,M11,O11+12) -> 12 | R11: =IF(K11=0,IF(AND(I11="Yes",J11<>""),J11,E11*(1+Inputs!$B$7)^(INT((O11-1)/12))),"")
A12: 111 | B12: 735 SF | C12: 735 | D12: Occupied | E12: 1525 | F12: 1450 | G12: 47 | H12: 46538 | K12: =IF(D12="Occupied",1,0) -> 1 | L12: =IF(AND(K12=1,I12="Yes"),1,0) -> 0 | M12: =IF(K12=1,IF(OR(H12="",H12<Inputs!$B$5),1,(YEAR(H12)-YEAR(Inputs!$B$5))*12+MONTH(H12)-MONTH(Inputs!$B$5)+2),"") -> 8 | N12: =IF(K12=0,IF(I12="Yes",COUNTIFS(K$2:K12,0,I$2:I12,"Yes")-1,COUNTIFS(K$2:K$121,0,I$2:I$121,"Yes")+COUNTIFS(K$2:K12,0,I$2:I12,"<>Yes")-1),"") | O12: =IF(K12=0,INT(N12/Inputs!$B$17)+1,"") | P12: =IF(K12=1,1,O12) -> 1 | Q12: =IF(K12=1,M12,O12+12) -> 8 | R12: =IF(K12=0,IF(AND(I12="Yes",J12<>""),J12,E12*(1+Inputs!$B$7)^(INT((O12-1)/12))),"")
A13: 112 | B13: 735 SF | C13: 735 | D13: Occupied | E13: 1525 | F13: 1555 | G13: 12 | H13: 46418 | K13: =IF(D13="Occupied",1,0) -> 1 | L13: =IF(AND(K13=1,I13="Yes"),1,0) -> 0 | M13: =IF(K13=1,IF(OR(H13="",H13<Inputs!$B$5),1,(YEAR(H13)-YEAR(Inputs!$B$5))*12+MONTH(H13)-MONTH(Inputs!$B$5)+2),"") -> 4 | N13: =IF(K13=0,IF(I13="Yes",COUNTIFS(K$2:K13,0,I$2:I13,"Yes")-1,COUNTIFS(K$2:K$121,0,I$2:I$121,"Yes")+COUNTIFS(K$2:K13,0,I$2:I13,"<>Yes")-1),"") | O13: =IF(K13=0,INT(N13/Inputs!$B$17)+1,"") | P13: =IF(K13=1,1,O13) -> 1 | Q13: =IF(K13=1,M13,O13+12) -> 4 | R13: =IF(K13=0,IF(AND(I13="Yes",J13<>""),J13,E13*(1+Inputs!$B$7)^(INT((O13-1)/12))),"")
A14: 113 | B14: 560 SF | C14: 560 | D14: Occupied | E14: 1295 | F14: 1320 | G14: 12 | H14: 46568 | K14: =IF(D14="Occupied",1,0) -> 1 | L14: =IF(AND(K14=1,I14="Yes"),1,0) -> 0 | M14: =IF(K14=1,IF(OR(H14="",H14<Inputs!$B$5),1,(YEAR(H14)-YEAR(Inputs!$B$5))*12+MONTH(H14)-MONTH(Inputs!$B$5)+2),"") -> 9 | N14: =IF(K14=0,IF(I14="Yes",COUNTIFS(K$2:K14,0,I$2:I14,"Yes")-1,COUNTIFS(K$2:K$121,0,I$2:I$121,"Yes")+COUNTIFS(K$2:K14,0,I$2:I14,"<>Yes")-1),"") | O14: =IF(K14=0,INT(N14/Inputs!$B$17)+1,"") | P14: =IF(K14=1,1,O14) -> 1 | Q14: =IF(K14=1,M14,O14+12) -> 9 | R14: =IF(K14=0,IF(AND(I14="Yes",J14<>""),J14,E14*(1+Inputs!$B$7)^(INT((O14-1)/12))),"")
A15: 114 | B15: 560 SF | C15: 560 | D15: Occupied | E15: 1295 | F15: 1245 | G15: 0 | H15: 46599 | K15: =IF(D15="Occupied",1,0) -> 1 | L15: =IF(AND(K15=1,I15="Yes"),1,0) -> 0 | M15: =IF(K15=1,IF(OR(H15="",H15<Inputs!$B$5),1,(YEAR(H15)-YEAR(Inputs!$B$5))*12+MONTH(H15)-MONTH(Inputs!$B$5)+2),"") -> 10 | N15: =IF(K15=0,IF(I15="Yes",COUNTIFS(K$2:K15,0,I$2:I15,"Yes")-1,COUNTIFS(K$2:K$121,0,I$2:I$121,"Yes")+COUNTIFS(K$2:K15,0,I$2:I15,"<>Yes")-1),"") | O15: =IF(K15=0,INT(N15/Inputs!$B$17)+1,"") | P15: =IF(K15=1,1,O15) -> 1 | Q15: =IF(K15=1,M15,O15+12) -> 10 | R15: =IF(K15=0,IF(AND(I15="Yes",J15<>""),J15,E15*(1+Inputs!$B$7)^(INT((O15-1)/12))),"")
A16: 115 | B16: 560 SF | C16: 560 | D16: Occupied | E16: 1295 | F16: 1030 | G16: 35 | H16: 46599 | K16: =IF(D16="Occupied",1,0) -> 1 | L16: =IF(AND(K16=1,I16="Yes"),1,0) -> 0 | M16: =IF(K16=1,IF(OR(H16="",H16<Inputs!$B$5),1,(YEAR(H16)-YEAR(Inputs!$B$5))*12+MONTH(H16)-MONTH(Inputs!$B$5)+2),"") -> 10 | N16: =IF(K16=0,IF(I16="Yes",COUNTIFS(K$2:K16,0,I$2:I16,"Yes")-1,COUNTIFS(K$2:K$121,0,I$2:I$121,"Yes")+COUNTIFS(K$2:K16,0,I$2:I16,"<>Yes")-1),"") | O16: =IF(K16=0,INT(N16/Inputs!$B$17)+1,"") | P16: =IF(K16=1,1,O16) -> 1 | Q16: =IF(K16=1,M16,O16+12) -> 10 | R16: =IF(K16=0,IF(AND(I16="Yes",J16<>""),J16,E16*(1+Inputs!$B$7)^(INT((O16-1)/12))),"")
A17: 116 | B17: 560 SF | C17: 560 | D17: Occupied | E17: 1295 | F17: 1330 | G17: 45 | H17: 46356 | K17: =IF(D17="Occupied",1,0) -> 1 | L17: =IF(AND(K17=1,I17="Yes"),1,0) -> 0 | M17: =IF(K17=1,IF(OR(H17="",H17<Inputs!$B$5),1,(YEAR(H17)-YEAR(Inputs!$B$5))*12+MONTH(H17)-MONTH(Inputs!$B$5)+2),"") -> 2 | N17: =IF(K17=0,IF(I17="Yes",COUNTIFS(K$2:K17,0,I$2:I17,"Yes")-1,COUNTIFS(K$2:K$121,0,I$2:I$121,"Yes")+COUNTIFS(K$2:K17,0,I$2:I17,"<>Yes")-1),"") | O17: =IF(K17=0,INT(N17/Inputs!$B$17)+1,"") | P17: =IF(K17=1,1,O17) -> 1 | Q17: =IF(K17=1,M17,O17+12) -> 2 | R17: =IF(K17=0,IF(AND(I17="Yes",J17<>""),J17,E17*(1+Inputs!$B$7)^(INT((O17-1)/12))),"")
A18: 117 | B18: 560 SF | C18: 560 | D18: Vacant | E18: 1295 | F18: 0 | G18: 0 | I18: Yes | K18: =IF(D18="Occupied",1,0) -> 0 | L18: =IF(AND(K18=1,I18="Yes"),1,0) -> 0 | M18: =IF(K18=1,IF(OR(H18="",H18<Inputs!$B$5),1,(YEAR(H18)-YEAR(Inputs!$B$5))*12+MONTH(H18)-MONTH(Inputs!$B$5)+2),"") | N18: =IF(K18=0,IF(I18="Yes",COUNTIFS(K$2:K18,0,I$2:I18,"Yes")-1,COUNTIFS(K$2:K$121,0,I$2:I$121,"Yes")+COUNTIFS(K$2:K18,0,I$2:I18,"<>Yes")-1),"") -> 0 | O18: =IF(K18=0,INT(N18/Inputs!$B$17)+1,"") -> 1 | P18: =IF(K18=1,1,O18) -> 1 | Q18: =IF(K18=1,M18,O18+12) -> 13 | R18: =IF(K18=0,IF(AND(I18="Yes",J18<>""),J18,E18*(1+Inputs!$B$7)^(INT((O18-1)/12))),"") -> 1295
A19: 118 | B19: 560 SF | C19: 560 | D19: Occupied | E19: 1295 | F19: 1225 | G19: 0 | H19: 46568 | K19: =IF(D19="Occupied",1,0) -> 1 | L19: =IF(AND(K19=1,I19="Yes"),1,0) -> 0 | M19: =IF(K19=1,IF(OR(H19="",H19<Inputs!$B$5),1,(YEAR(H19)-YEAR(Inputs!$B$5))*12+MONTH(H19)-MONTH(Inputs!$B$5)+2),"") -> 9 | N19: =IF(K19=0,IF(I19="Yes",COUNTIFS(K$2:K19,0,I$2:I19,"Yes")-1,COUNTIFS(K$2:K$121,0,I$2:I$121,"Yes")+COUNTIFS(K$2:K19,0,I$2:I19,"<>Yes")-1),"") | O19: =IF(K19=0,INT(N19/Inputs!$B$17)+1,"") | P19: =IF(K19=1,1,O19) -> 1 | Q19: =IF(K19=1,M19,O19+12) -> 9 | R19: =IF(K19=0,IF(AND(I19="Yes",J19<>""),J19,E19*(1+Inputs!$B$7)^(INT((O19-1)/12))),"")
A20: 119 | B20: 560 SF | C20: 560 | D20: Occupied | E20: 1295 | F20: 1270 | G20: 0 | H20: 46568 | K20: =IF(D20="Occupied",1,0) -> 1 | L20: =IF(AND(K20=1,I20="Yes"),1,0) -> 0 | M20: =IF(K20=1,IF(OR(H20="",H20<Inputs!$B$5),1,(YEAR(H20)-YEAR(Inputs!$B$5))*12+MONTH(H20)-MONTH(Inputs!$B$5)+2),"") -> 9 | N20: =IF(K20=0,IF(I20="Yes",COUNTIFS(K$2:K20,0,I$2:I20,"Yes")-1,COUNTIFS(K$2:K$121,0,I$2:I$121,"Yes")+COUNTIFS(K$2:K20,0,I$2:I20,"<>Yes")-1),"") | O20: =IF(K20=0,INT(N20/Inputs!$B$17)+1,"") | P20: =IF(K20=1,1,O20) -> 1 | Q20: =IF(K20=1,M20,O20+12) -> 9 | R20: =IF(K20=0,IF(AND(I20="Yes",J20<>""),J20,E20*(1+Inputs!$B$7)^(INT((O20-1)/12))),"")
A21: 120 | B21: 560 SF | C21: 560 | D21: Occupied | E21: 1295 | F21: 1190 | G21: 0 | H21: 46568 | K21: =IF(D21="Occupied",1,0) -> 1 | L21: =IF(AND(K21=1,I21="Yes"),1,0) -> 0 | M21: =IF(K21=1,IF(OR(H21="",H21<Inputs!$B$5),1,(YEAR(H21)-YEAR(Inputs!$B$5))*12+MONTH(H21)-MONTH(Inputs!$B$5)+2),"") -> 9 | N21: =IF(K21=0,IF(I21="Yes",COUNTIFS(K$2:K21,0,I$2:I21,"Yes")-1,COUNTIFS(K$2:K$121,0,I$2:I$121,"Yes")+COUNTIFS(K$2:K21,0,I$2:I21,"<>Yes")-1),"") | O21: =IF(K21=0,INT(N21/Inputs!$B$17)+1,"") | P21: =IF(K21=1,1,O21) -> 1 | Q21: =IF(K21=1,M21,O21+12) -> 9 | R21: =IF(K21=0,IF(AND(I21="Yes",J21<>""),J21,E21*(1+Inputs!$B$7)^(INT((O21-1)/12))),"")
A22: 121 | B22: 960 SF | C22: 960 | D22: Occupied | E22: 1850 | F22: 1800 | G22: 40 | H22: 46387 | K22: =IF(D22="Occupied",1,0) -> 1 | L22: =IF(AND(K22=1,I22="Yes"),1,0) -> 0 | M22: =IF(K22=1,IF(OR(H22="",H22<Inputs!$B$5),1,(YEAR(H22)-YEAR(Inputs!$B$5))*12+MONTH(H22)-MONTH(Inputs!$B$5)+2),"") -> 3 | N22: =IF(K22=0,IF(I22="Yes",COUNTIFS(K$2:K22,0,I$2:I22,"Yes")-1,COUNTIFS(K$2:K$121,0,I$2:I$121,"Yes")+COUNTIFS(K$2:K22,0,I$2:I22,"<>Yes")-1),"") | O22: =IF(K22=0,INT(N22/Inputs!$B$17)+1,"") | P22: =IF(K22=1,1,O22) -> 1 | Q22: =IF(K22=1,M22,O22+12) -> 3 | R22: =IF(K22=0,IF(AND(I22="Yes",J22<>""),J22,E22*(1+Inputs!$B$7)^(INT((O22-1)/12))),"")
A23: 122 | B23: 960 SF | C23: 960 | D23: Occupied | E23: 1850 | F23: 1725 | G23: 0 | H23: 46599 | K23: =IF(D23="Occupied",1,0) -> 1 | L23: =IF(AND(K23=1,I23="Yes"),1,0) -> 0 | M23: =IF(K23=1,IF(OR(H23="",H23<Inputs!$B$5),1,(YEAR(H23)-YEAR(Inputs!$B$5))*12+MONTH(H23)-MONTH(Inputs!$B$5)+2),"") -> 10 | N23: =IF(K23=0,IF(I23="Yes",COUNTIFS(K$2:K23,0,I$2:I23,"Yes")-1,COUNTIFS(K$2:K$121,0,I$2:I$121,"Yes")+COUNTIFS(K$2:K23,0,I$2:I23,"<>Yes")-1),"") | O23: =IF(K23=0,INT(N23/Inputs!$B$17)+1,"") | P23: =IF(K23=1,1,O23) -> 1 | Q23: =IF(K23=1,M23,O23+12) -> 10 | R23: =IF(K23=0,IF(AND(I23="Yes",J23<>""),J23,E23*(1+Inputs!$B$7)^(INT((O23-1)/12))),"")
A24: 123 | B24: 960 SF | C24: 960 | D24: Occupied | E24: 1850 | F24: 1750 | G24: 45 | H24: 46507 | K24: =IF(D24="Occupied",1,0) -> 1 | L24: =IF(AND(K24=1,I24="Yes"),1,0) -> 0 | M24: =IF(K24=1,IF(OR(H24="",H24<Inputs!$B$5),1,(YEAR(H24)-YEAR(Inputs!$B$5))*12+MONTH(H24)-MONTH(Inputs!$B$5)+2),"") -> 7 | N24: =IF(K24=0,IF(I24="Yes",COUNTIFS(K$2:K24,0,I$2:I24,"Yes")-1,COUNTIFS(K$2:K$121,0,I$2:I$121,"Yes")+COUNTIFS(K$2:K24,0,I$2:I24,"<>Yes")-1),"") | O24: =IF(K24=0,INT(N24/Inputs!$B$17)+1,"") | P24: =IF(K24=1,1,O24) -> 1 | Q24: =IF(K24=1,M24,O24+12) -> 7 | R24: =IF(K24=0,IF(AND(I24="Yes",J24<>""),J24,E24*(1+Inputs!$B$7)^(INT((O24-1)/12))),"")
A25: 124 | B25: 960 SF | C25: 960 | D25: Occupied | E25: 1850 | F25: 1680 | G25: 80 | H25: 46630 | K25: =IF(D25="Occupied",1,0) -> 1 | L25: =IF(AND(K25=1,I25="Yes"),1,0) -> 0 | M25: =IF(K25=1,IF(OR(H25="",H25<Inputs!$B$5),1,(YEAR(H25)-YEAR(Inputs!$B$5))*12+MONTH(H25)-MONTH(Inputs!$B$5)+2),"") -> 11 | N25: =IF(K25=0,IF(I25="Yes",COUNTIFS(K$2:K25,0,I$2:I25,"Yes")-1,COUNTIFS(K$2:K$121,0,I$2:I$121,"Yes")+COUNTIFS(K$2:K25,0,I$2:I25,"<>Yes")-1),"") | O25: =IF(K25=0,INT(N25/Inputs!$B$17)+1,"") | P25: =IF(K25=1,1,O25) -> 1 | Q25: =IF(K25=1,M25,O25+12) -> 11 | R25: =IF(K25=0,IF(AND(I25="Yes",J25<>""),J25,E25*(1+Inputs!$B$7)^(INT((O25-1)/12))),"")
A26: 125 | B26: 960 SF | C26: 960 | D26: Occupied | E26: 1850 | F26: 1895 | G26: 0 | H26: 46660 | K26: =IF(D26="Occupied",1,0) -> 1 | L26: =IF(AND(K26=1,I26="Yes"),1,0) -> 0 | M26: =IF(K26=1,IF(OR(H26="",H26<Inputs!$B$5),1,(YEAR(H26)-YEAR(Inputs!$B$5))*12+MONTH(H26)-MONTH(Inputs!$B$5)+2),"") -> 12 | N26: =IF(K26=0,IF(I26="Yes",COUNTIFS(K$2:K26,0,I$2:I26,"Yes")-1,COUNTIFS(K$2:K$121,0,I$2:I$121,"Yes")+COUNTIFS(K$2:K26,0,I$2:I26,"<>Yes")-1),"") | O26: =IF(K26=0,INT(N26/Inputs!$B$17)+1,"") | P26: =IF(K26=1,1,O26) -> 1 | Q26: =IF(K26=1,M26,O26+12) -> 12 | R26: =IF(K26=0,IF(AND(I26="Yes",J26<>""),J26,E26*(1+Inputs!$B$7)^(INT((O26-1)/12))),"")
A27: 126 | B27: 960 SF | C27: 960 | D27: Occupied | E27: 1850 | F27: 1895 | G27: 0 | H27: 46234 | K27: =IF(D27="Occupied",1,0) -> 1 | L27: =IF(AND(K27=1,I27="Yes"),1,0) -> 0 | M27: =IF(K27=1,IF(OR(H27="",H27<Inputs!$B$5),1,(YEAR(H27)-YEAR(Inputs!$B$5))*12+MONTH(H27)-MONTH(Inputs!$B$5)+2),"") -> 1 | N27: =IF(K27=0,IF(I27="Yes",COUNTIFS(K$2:K27,0,I$2:I27,"Yes")-1,COUNTIFS(K$2:K$121,0,I$2:I$121,"Yes")+COUNTIFS(K$2:K27,0,I$2:I27,"<>Yes")-1),"") | O27: =IF(K27=0,INT(N27/Inputs!$B$17)+1,"") | P27: =IF(K27=1,1,O27) -> 1 | Q27: =IF(K27=1,M27,O27+12) -> 1 | R27: =IF(K27=0,IF(AND(I27="Yes",J27<>""),J27,E27*(1+Inputs!$B$7)^(INT((O27-1)/12))),"")
A28: 127 | B28: 960 SF | C28: 960 | D28: Occupied | E28: 1850 | F28: 1855 | G28: 12 | H28: 46418 | K28: =IF(D28="Occupied",1,0) -> 1 | L28: =IF(AND(K28=1,I28="Yes"),1,0) -> 0 | M28: =IF(K28=1,IF(OR(H28="",H28<Inputs!$B$5),1,(YEAR(H28)-YEAR(Inputs!$B$5))*12+MONTH(H28)-MONTH(Inputs!$B$5)+2),"") -> 4 | N28: =IF(K28=0,IF(I28="Yes",COUNTIFS(K$2:K28,0,I$2:I28,"Yes")-1,COUNTIFS(K$2:K$121,0,I$2:I$121,"Yes")+COUNTIFS(K$2:K28,0,I$2:I28,"<>Yes")-1),"") | O28: =IF(K28=0,INT(N28/Inputs!$B$17)+1,"") | P28: =IF(K28=1,1,O28) -> 1 | Q28: =IF(K28=1,M28,O28+12) -> 4 | R28: =IF(K28=0,IF(AND(I28="Yes",J28<>""),J28,E28*(1+Inputs!$B$7)^(INT((O28-1)/12))),"")
A29: 128 | B29: 1180 SF | C29: 1180 | D29: Occupied | E29: 2240 | F29: 2130 | G29: 12 | H29: 46630 | K29: =IF(D29="Occupied",1,0) -> 1 | L29: =IF(AND(K29=1,I29="Yes"),1,0) -> 0 | M29: =IF(K29=1,IF(OR(H29="",H29<Inputs!$B$5),1,(YEAR(H29)-YEAR(Inputs!$B$5))*12+MONTH(H29)-MONTH(Inputs!$B$5)+2),"") -> 11 | N29: =IF(K29=0,IF(I29="Yes",COUNTIFS(K$2:K29,0,I$2:I29,"Yes")-1,COUNTIFS(K$2:K$121,0,I$2:I$121,"Yes")+COUNTIFS(K$2:K29,0,I$2:I29,"<>Yes")-1),"") | O29: =IF(K29=0,INT(N29/Inputs!$B$17)+1,"") | P29: =IF(K29=1,1,O29) -> 1 | Q29: =IF(K29=1,M29,O29+12) -> 11 | R29: =IF(K29=0,IF(AND(I29="Yes",J29<>""),J29,E29*(1+Inputs!$B$7)^(INT((O29-1)/12))),"")
A30: 129 | B30: 1180 SF | C30: 1180 | D30: Occupied | E30: 2240 | F30: 2280 | G30: 45 | H30: 46538 | K30: =IF(D30="Occupied",1,0) -> 1 | L30: =IF(AND(K30=1,I30="Yes"),1,0) -> 0 | M30: =IF(K30=1,IF(OR(H30="",H30<Inputs!$B$5),1,(YEAR(H30)-YEAR(Inputs!$B$5))*12+MONTH(H30)-MONTH(Inputs!$B$5)+2),"") -> 8 | N30: =IF(K30=0,IF(I30="Yes",COUNTIFS(K$2:K30,0,I$2:I30,"Yes")-1,COUNTIFS(K$2:K$121,0,I$2:I$121,"Yes")+COUNTIFS(K$2:K30,0,I$2:I30,"<>Yes")-1),"") | O30: =IF(K30=0,INT(N30/Inputs!$B$17)+1,"") | P30: =IF(K30=1,1,O30) -> 1 | Q30: =IF(K30=1,M30,O30+12) -> 8 | R30: =IF(K30=0,IF(AND(I30="Yes",J30<>""),J30,E30*(1+Inputs!$B$7)^(INT((O30-1)/12))),"")
... A39: 208 | B39: 735 SF | C39: 735 | D39: Occupied | E39: 1525 | F39: 1540 | G39: 65 | H39: 46387 | K39: =IF(D39="Occupied",1,0) -> 1 | L39: =IF(AND(K39=1,I39="Yes"),1,0) -> 0 | M39: =IF(K39=1,IF(OR(H39="",H39<Inputs!$B$5),1,(YEAR(H39)-YEAR(Inputs!$B$5))*12+MONTH(H39)-MONTH(Inputs!$B$5)+2),"") -> 3 | N39: =IF(K39=0,IF(I39="Yes",COUNTIFS(K$2:K39,0,I$2:I39,"Yes")-1,COUNTIFS(K$2:K$121,0,I$2:I$121,"Yes")+COUNTIFS(K$2:K39,0,I$2:I39,"<>Yes")-1),"") | O39: =IF(K39=0,INT(N39/Inputs!$B$17)+1,"") | P39: =IF(K39=1,1,O39) -> 1 | Q39: =IF(K39=1,M39,O39+12) -> 3 | R39: =IF(K39=0,IF(AND(I39="Yes",J39<>""),J39,E39*(1+Inputs!$B$7)^(INT((O39-1)/12))),"")
A40: 209 | B40: 735 SF | C40: 735 | D40: Vacant | E40: 1525 | F40: 0 | G40: 0 | K40: =IF(D40="Occupied",1,0) -> 0 | L40: =IF(AND(K40=1,I40="Yes"),1,0) -> 0 | M40: =IF(K40=1,IF(OR(H40="",H40<Inputs!$B$5),1,(YEAR(H40)-YEAR(Inputs!$B$5))*12+MONTH(H40)-MONTH(Inputs!$B$5)+2),"") | N40: =IF(K40=0,IF(I40="Yes",COUNTIFS(K$2:K40,0,I$2:I40,"Yes")-1,COUNTIFS(K$2:K$121,0,I$2:I$121,"Yes")+COUNTIFS(K$2:K40,0,I$2:I40,"<>Yes")-1),"") -> 4 | O40: =IF(K40=0,INT(N40/Inputs!$B$17)+1,"") -> 1 | P40: =IF(K40=1,1,O40) -> 1 | Q40: =IF(K40=1,M40,O40+12) -> 13 | R40: =IF(K40=0,IF(AND(I40="Yes",J40<>""),J40,E40*(1+Inputs!$B$7)^(INT((O40-1)/12))),"") -> 1525
A41: 210 | B41: 735 SF | C41: 735 | D41: Occupied | E41: 1525 | F41: 1455 | G41: 50 | H41: 46538 | K41: =IF(D41="Occupied",1,0) -> 1 | L41: =IF(AND(K41=1,I41="Yes"),1,0) -> 0 | M41: =IF(K41=1,IF(OR(H41="",H41<Inputs!$B$5),1,(YEAR(H41)-YEAR(Inputs!$B$5))*12+MONTH(H41)-MONTH(Inputs!$B$5)+2),"") -> 8 | N41: =IF(K41=0,IF(I41="Yes",COUNTIFS(K$2:K41,0,I$2:I41,"Yes")-1,COUNTIFS(K$2:K$121,0,I$2:I$121,"Yes")+COUNTIFS(K$2:K41,0,I$2:I41,"<>Yes")-1),"") | O41: =IF(K41=0,INT(N41/Inputs!$B$17)+1,"") | P41: =IF(K41=1,1,O41) -> 1 | Q41: =IF(K41=1,M41,O41+12) -> 8 | R41: =IF(K41=0,IF(AND(I41="Yes",J41<>""),J41,E41*(1+Inputs!$B$7)^(INT((O41-1)/12))),"")
A42: 211 | B42: 735 SF | C42: 735 | D42: Occupied | E42: 1525 | F42: 1375 | G42: 45 | H42: 46418 | K42: =IF(D42="Occupied",1,0) -> 1 | L42: =IF(AND(K42=1,I42="Yes"),1,0) -> 0 | M42: =IF(K42=1,IF(OR(H42="",H42<Inputs!$B$5),1,(YEAR(H42)-YEAR(Inputs!$B$5))*12+MONTH(H42)-MONTH(Inputs!$B$5)+2),"") -> 4 | N42: =IF(K42=0,IF(I42="Yes",COUNTIFS(K$2:K42,0,I$2:I42,"Yes")-1,COUNTIFS(K$2:K$121,0,I$2:I$121,"Yes")+COUNTIFS(K$2:K42,0,I$2:I42,"<>Yes")-1),"") | O42: =IF(K42=0,INT(N42/Inputs!$B$17)+1,"") | P42: =IF(K42=1,1,O42) -> 1 | Q42: =IF(K42=1,M42,O42+12) -> 4 | R42: =IF(K42=0,IF(AND(I42="Yes",J42<>""),J42,E42*(1+Inputs!$B$7)^(INT((O42-1)/12))),"")
A43: 212 | B43: 735 SF | C43: 735 | D43: Occupied | E43: 1525 | F43: 1390 | G43: 0 | H43: 46568 | K43: =IF(D43="Occupied",1,0) -> 1 | L43: =IF(AND(K43=1,I43="Yes"),1,0) -> 0 | M43: =IF(K43=1,IF(OR(H43="",H43<Inputs!$B$5),1,(YEAR(H43)-YEAR(Inputs!$B$5))*12+MONTH(H43)-MONTH(Inputs!$B$5)+2),"") -> 9 | N43: =IF(K43=0,IF(I43="Yes",COUNTIFS(K$2:K43,0,I$2:I43,"Yes")-1,COUNTIFS(K$2:K$121,0,I$2:I$121,"Yes")+COUNTIFS(K$2:K43,0,I$2:I43,"<>Yes")-1),"") | O43: =IF(K43=0,INT(N43/Inputs!$B$17)+1,"") | P43: =IF(K43=1,1,O43) -> 1 | Q43: =IF(K43=1,M43,O43+12) -> 9 | R43: =IF(K43=0,IF(AND(I43="Yes",J43<>""),J43,E43*(1+Inputs!$B$7)^(INT((O43-1)/12))),"")
A44: 213 | B44: 560 SF | C44: 560 | D44: Occupied | E44: 1295 | F44: 1195 | G44: 85 | H44: 46660 | K44: =IF(D44="Occupied",1,0) -> 1 | L44: =IF(AND(K44=1,I44="Yes"),1,0) -> 0 | M44: =IF(K44=1,IF(OR(H44="",H44<Inputs!$B$5),1,(YEAR(H44)-YEAR(Inputs!$B$5))*12+MONTH(H44)-MONTH(Inputs!$B$5)+2),"") -> 12 | N44: =IF(K44=0,IF(I44="Yes",COUNTIFS(K$2:K44,0,I$2:I44,"Yes")-1,COUNTIFS(K$2:K$121,0,I$2:I$121,"Yes")+COUNTIFS(K$2:K44,0,I$2:I44,"<>Yes")-1),"") | O44: =IF(K44=0,INT(N44/Inputs!$B$17)+1,"") | P44: =IF(K44=1,1,O44) -> 1 | Q44: =IF(K44=1,M44,O44+12) -> 12 | R44: =IF(K44=0,IF(AND(I44="Yes",J44<>""),J44,E44*(1+Inputs!$B$7)^(INT((O44-1)/12))),"")
A45: 214 | B45: 560 SF | C45: 560 | D45: Occupied | E45: 1295 | F45: 1260 | G45: 12 | H45: 46326 | I45: Yes | K45: =IF(D45="Occupied",1,0) -> 1 | L45: =IF(AND(K45=1,I45="Yes"),1,0) -> 1 | M45: =IF(K45=1,IF(OR(H45="",H45<Inputs!$B$5),1,(YEAR(H45)-YEAR(Inputs!$B$5))*12+MONTH(H45)-MONTH(Inputs!$B$5)+2),"") -> 1 | N45: =IF(K45=0,IF(I45="Yes",COUNTIFS(K$2:K45,0,I$2:I45,"Yes")-1,COUNTIFS(K$2:K$121,0,I$2:I$121,"Yes")+COUNTIFS(K$2:K45,0,I$2:I45,"<>Yes")-1),"") | O45: =IF(K45=0,INT(N45/Inputs!$B$17)+1,"") | P45: =IF(K45=1,1,O45) -> 1 | Q45: =IF(K45=1,M45,O45+12) -> 1 | R45: =IF(K45=0,IF(AND(I45="Yes",J45<>""),J45,E45*(1+Inputs!$B$7)^(INT((O45-1)/12))),"")
A46: 215 | B46: 560 SF | C46: 560 | D46: Occupied | E46: 1295 | F46: 1310 | G46: 75 | H46: 46630 | K46: =IF(D46="Occupied",1,0) -> 1 | L46: =IF(AND(K46=1,I46="Yes"),1,0) -> 0 | M46: =IF(K46=1,IF(OR(H46="",H46<Inputs!$B$5),1,(YEAR(H46)-YEAR(Inputs!$B$5))*12+MONTH(H46)-MONTH(Inputs!$B$5)+2),"") -> 11 | N46: =IF(K46=0,IF(I46="Yes",COUNTIFS(K$2:K46,0,I$2:I46,"Yes")-1,COUNTIFS(K$2:K$121,0,I$2:I$121,"Yes")+COUNTIFS(K$2:K46,0,I$2:I46,"<>Yes")-1),"") | O46: =IF(K46=0,INT(N46/Inputs!$B$17)+1,"") | P46: =IF(K46=1,1,O46) -> 1 | Q46: =IF(K46=1,M46,O46+12) -> 11 | R46: =IF(K46=0,IF(AND(I46="Yes",J46<>""),J46,E46*(1+Inputs!$B$7)^(INT((O46-1)/12))),"")
A47: 216 | B47: 560 SF | C47: 560 | D47: Occupied | E47: 1295 | F47: 1220 | G47: 25 | H47: 46660 | K47: =IF(D47="Occupied",1,0) -> 1 | L47: =IF(AND(K47=1,I47="Yes"),1,0) -> 0 | M47: =IF(K47=1,IF(OR(H47="",H47<Inputs!$B$5),1,(YEAR(H47)-YEAR(Inputs!$B$5))*12+MONTH(H47)-MONTH(Inputs!$B$5)+2),"") -> 12 | N47: =IF(K47=0,IF(I47="Yes",COUNTIFS(K$2:K47,0,I$2:I47,"Yes")-1,COUNTIFS(K$2:K$121,0,I$2:I$121,"Yes")+COUNTIFS(K$2:K47,0,I$2:I47,"<>Yes")-1),"") | O47: =IF(K47=0,INT(N47/Inputs!$B$17)+1,"") | P47: =IF(K47=1,1,O47) -> 1 | Q47: =IF(K47=1,M47,O47+12) -> 12 | R47: =IF(K47=0,IF(AND(I47="Yes",J47<>""),J47,E47*(1+Inputs!$B$7)^(INT((O47-1)/12))),"")
A48: 217 | B48: 560 SF | C48: 560 | D48: Occupied | E48: 1295 | F48: 1330 | G48: 0 | H48: 46507 | K48: =IF(D48="Occupied",1,0) -> 1 | L48: =IF(AND(K48=1,I48="Yes"),1,0) -> 0 | M48: =IF(K48=1,IF(OR(H48="",H48<Inputs!$B$5),1,(YEAR(H48)-YEAR(Inputs!$B$5))*12+MONTH(H48)-MONTH(Inputs!$B$5)+2),"") -> 7 | N48: =IF(K48=0,IF(I48="Yes",COUNTIFS(K$2:K48,0,I$2:I48,"Yes")-1,COUNTIFS(K$2:K$121,0,I$2:I$121,"Yes")+COUNTIFS(K$2:K48,0,I$2:I48,"<>Yes")-1),"") | O48: =IF(K48=0,INT(N48/Inputs!$B$17)+1,"") | P48: =IF(K48=1,1,O48) -> 1 | Q48: =IF(K48=1,M48,O48+12) -> 7 | R48: =IF(K48=0,IF(AND(I48="Yes",J48<>""),J48,E48*(1+Inputs!$B$7)^(INT((O48-1)/12))),"")
...

Sheet Mkt
A1: Month | B1: Market rent $/mo | C1: 1 | D1: 2 | E1: 3 | F1: 4 | G1: 5 | H1: 6 | I1: 7 | J1: 8 | K1: 9 | L1: 10 | M1: 11 | N1: 12 | O1: 13 | P1: 14 | Q1: 15 | R1: 16 | S1: 17 | T1: 18 | U1: 19 | V1: 20 | W1: 21 | X1: 22 | Y1: 23 | Z1: 24 | AA1: 25 | AB1: 26 | AC1: 27 | AD1: 28 | AE1: 29 | AF1: 30 | AG1: 31 | AH1: 32 | AI1: 33 | AJ1: 34 | AK1: 35 | AL1: 36 | AM1: 37 | AN1: 38 | AO1: 39 | AP1: 40 | AQ1: 41 | AR1: 42 | AS1: 43 | AT1: 44 | AU1: 45 | AV1: 46 | AW1: 47 | AX1: 48 | AY1: 49 | AZ1: 50 | BA1: 51 | BB1: 52 | BC1: 53 | BD1: 54 | BE1: 55 | BF1: 56 | BG1: 57 | BH1: 58 | BI1: 59 | BJ1: 60 | BK1: 61 | BL1: 62 | BM1: 63 | BN1: 64 | BO1: 65 | BP1: 66 | BQ1: 67 | BR1: 68 | BS1: 69 | BT1: 70 | BU1: 71 | BV1: 72 | BW1: 73 | BX1: 74 | BY1: 75 | BZ1: 76 | CA1: 77 | CB1: 78 | CC1: 79 | CD1: 80 | CE1: 81 | CF1: 82 | CG1: 83 | CH1: 84 | CI1: 85 | CJ1: 86 | CK1: 87 | CL1: 88 | CM1: 89 | CN1: 90 | CO1: 91 | CP1: 92 | CQ1: 93 | CR1: 94 | CS1: 95 | CT1: 96 | CU1: 97 | CV1: 98 | CW1: 99 | CX1: 100 | CY1: 101 | CZ1: 102 | DA1: 103 | DB1: 104 | DC1: 105 | DD1: 106 | DE1: 107 | DF1: 108 | DG1: 109 | DH1: 110 | DI1: 111 | DJ1: 112 | DK1: 113 | DL1: 114 | DM1: 115 | DN1: 116 | DO1: 117 | DP1: 118 | DQ1: 119 | DR1: 120 | DS1: 121 | DT1: 122 | DU1: 123 | DV1: 124 | DW1: 125 | DX1: 126 | DY1: 127 | DZ1: 128 | EA1: 129 | EB1: 130 | EC1: 131 | ED1: 132
A2: Year | C2: =ROUNDUP(C1/12,0) -> 1 | D2: =ROUNDUP(D1/12,0) -> 1 | E2: =ROUNDUP(E1/12,0) -> 1 | F2: =ROUNDUP(F1/12,0) -> 1 | G2: =ROUNDUP(G1/12,0) -> 1 | H2: =ROUNDUP(H1/12,0) -> 1 | I2: =ROUNDUP(I1/12,0) -> 1 | J2: =ROUNDUP(J1/12,0) -> 1 | ... ED2: =ROUNDUP(ED1/12,0) -> 11
A3: =Units!A2 -> 101 | C3: =Units!$E2*(1+Inputs!$B$7)^(C$2-1) -> 1525 | D3: =Units!$E2*(1+Inputs!$B$7)^(D$2-1) -> 1525 | E3: =Units!$E2*(1+Inputs!$B$7)^(E$2-1) -> 1525 | F3: =Units!$E2*(1+Inputs!$B$7)^(F$2-1) -> 1525 | G3: =Units!$E2*(1+Inputs!$B$7)^(G$2-1) -> 1525 | H3: =Units!$E2*(1+Inputs!$B$7)^(H$2-1) -> 1525 | I3: =Units!$E2*(1+Inputs!$B$7)^(I$2-1) -> 1525 | J3: =Units!$E2*(1+Inputs!$B$7)^(J$2-1) -> 1525 | ... ED3: =Units!$E2*(1+Inputs!$B$7)^(ED$2-1) -> 2049.4725
A4: =Units!A3 -> 102 | C4: =Units!$E3*(1+Inputs!$B$7)^(C$2-1) -> 1525 | D4: =Units!$E3*(1+Inputs!$B$7)^(D$2-1) -> 1525 | E4: =Units!$E3*(1+Inputs!$B$7)^(E$2-1) -> 1525 | F4: =Units!$E3*(1+Inputs!$B$7)^(F$2-1) -> 1525 | G4: =Units!$E3*(1+Inputs!$B$7)^(G$2-1) -> 1525 | H4: =Units!$E3*(1+Inputs!$B$7)^(H$2-1) -> 1525 | I4: =Units!$E3*(1+Inputs!$B$7)^(I$2-1) -> 1525 | J4: =Units!$E3*(1+Inputs!$B$7)^(J$2-1) -> 1525 | ... ED4: =Units!$E3*(1+Inputs!$B$7)^(ED$2-1) -> 2049.4725
A5: =Units!A4 -> 103 | C5: =Units!$E4*(1+Inputs!$B$7)^(C$2-1) -> 1525 | D5: =Units!$E4*(1+Inputs!$B$7)^(D$2-1) -> 1525 | E5: =Units!$E4*(1+Inputs!$B$7)^(E$2-1) -> 1525 | F5: =Units!$E4*(1+Inputs!$B$7)^(F$2-1) -> 1525 | G5: =Units!$E4*(1+Inputs!$B$7)^(G$2-1) -> 1525 | H5: =Units!$E4*(1+Inputs!$B$7)^(H$2-1) -> 1525 | I5: =Units!$E4*(1+Inputs!$B$7)^(I$2-1) -> 1525 | J5: =Units!$E4*(1+Inputs!$B$7)^(J$2-1) -> 1525 | ... ED5: =Units!$E4*(1+Inputs!$B$7)^(ED$2-1) -> 2049.4725
A6: =Units!A5 -> 104 | C6: =Units!$E5*(1+Inputs!$B$7)^(C$2-1) -> 1525 | D6: =Units!$E5*(1+Inputs!$B$7)^(D$2-1) -> 1525 | E6: =Units!$E5*(1+Inputs!$B$7)^(E$2-1) -> 1525 | F6: =Units!$E5*(1+Inputs!$B$7)^(F$2-1) -> 1525 | G6: =Units!$E5*(1+Inputs!$B$7)^(G$2-1) -> 1525 | H6: =Units!$E5*(1+Inputs!$B$7)^(H$2-1) -> 1525 | I6: =Units!$E5*(1+Inputs!$B$7)^(I$2-1) -> 1525 | J6: =Units!$E5*(1+Inputs!$B$7)^(J$2-1) -> 1525 | ... ED6: =Units!$E5*(1+Inputs!$B$7)^(ED$2-1) -> 2049.4725
A7: =Units!A6 -> 105 | C7: =Units!$E6*(1+Inputs!$B$7)^(C$2-1) -> 1525 | D7: =Units!$E6*(1+Inputs!$B$7)^(D$2-1) -> 1525 | E7: =Units!$E6*(1+Inputs!$B$7)^(E$2-1) -> 1525 | F7: =Units!$E6*(1+Inputs!$B$7)^(F$2-1) -> 1525 | G7: =Units!$E6*(1+Inputs!$B$7)^(G$2-1) -> 1525 | H7: =Units!$E6*(1+Inputs!$B$7)^(H$2-1) -> 1525 | I7: =Units!$E6*(1+Inputs!$B$7)^(I$2-1) -> 1525 | J7: =Units!$E6*(1+Inputs!$B$7)^(J$2-1) -> 1525 | ... ED7: =Units!$E6*(1+Inputs!$B$7)^(ED$2-1) -> 2049.4725
A8: =Units!A7 -> 106 | C8: =Units!$E7*(1+Inputs!$B$7)^(C$2-1) -> 1525 | D8: =Units!$E7*(1+Inputs!$B$7)^(D$2-1) -> 1525 | E8: =Units!$E7*(1+Inputs!$B$7)^(E$2-1) -> 1525 | F8: =Units!$E7*(1+Inputs!$B$7)^(F$2-1) -> 1525 | G8: =Units!$E7*(1+Inputs!$B$7)^(G$2-1) -> 1525 | H8: =Units!$E7*(1+Inputs!$B$7)^(H$2-1) -> 1525 | I8: =Units!$E7*(1+Inputs!$B$7)^(I$2-1) -> 1525 | J8: =Units!$E7*(1+Inputs!$B$7)^(J$2-1) -> 1525 | ... ED8: =Units!$E7*(1+Inputs!$B$7)^(ED$2-1) -> 2049.4725
A9: =Units!A8 -> 107 | C9: =Units!$E8*(1+Inputs!$B$7)^(C$2-1) -> 1525 | D9: =Units!$E8*(1+Inputs!$B$7)^(D$2-1) -> 1525 | E9: =Units!$E8*(1+Inputs!$B$7)^(E$2-1) -> 1525 | F9: =Units!$E8*(1+Inputs!$B$7)^(F$2-1) -> 1525 | G9: =Units!$E8*(1+Inputs!$B$7)^(G$2-1) -> 1525 | H9: =Units!$E8*(1+Inputs!$B$7)^(H$2-1) -> 1525 | I9: =Units!$E8*(1+Inputs!$B$7)^(I$2-1) -> 1525 | J9: =Units!$E8*(1+Inputs!$B$7)^(J$2-1) -> 1525 | ... ED9: =Units!$E8*(1+Inputs!$B$7)^(ED$2-1) -> 2049.4725
A10: =Units!A9 -> 108 | C10: =Units!$E9*(1+Inputs!$B$7)^(C$2-1) -> 1525 | D10: =Units!$E9*(1+Inputs!$B$7)^(D$2-1) -> 1525 | E10: =Units!$E9*(1+Inputs!$B$7)^(E$2-1) -> 1525 | F10: =Units!$E9*(1+Inputs!$B$7)^(F$2-1) -> 1525 | G10: =Units!$E9*(1+Inputs!$B$7)^(G$2-1) -> 1525 | H10: =Units!$E9*(1+Inputs!$B$7)^(H$2-1) -> 1525 | I10: =Units!$E9*(1+Inputs!$B$7)^(I$2-1) -> 1525 | J10: =Units!$E9*(1+Inputs!$B$7)^(J$2-1) -> 1525 | ... ED10: =Units!$E9*(1+Inputs!$B$7)^(ED$2-1) -> 2049.4725
A11: =Units!A10 -> 109 | C11: =Units!$E10*(1+Inputs!$B$7)^(C$2-1) -> 1525 | D11: =Units!$E10*(1+Inputs!$B$7)^(D$2-1) -> 1525 | E11: =Units!$E10*(1+Inputs!$B$7)^(E$2-1) -> 1525 | F11: =Units!$E10*(1+Inputs!$B$7)^(F$2-1) -> 1525 | G11: =Units!$E10*(1+Inputs!$B$7)^(G$2-1) -> 1525 | H11: =Units!$E10*(1+Inputs!$B$7)^(H$2-1) -> 1525 | I11: =Units!$E10*(1+Inputs!$B$7)^(I$2-1) -> 1525 | J11: =Units!$E10*(1+Inputs!$B$7)^(J$2-1) -> 1525 | ... ED11: =Units!$E10*(1+Inputs!$B$7)^(ED$2-1) -> 2049.4725
A12: =Units!A11 -> 110 | C12: =Units!$E11*(1+Inputs!$B$7)^(C$2-1) -> 1525 | D12: =Units!$E11*(1+Inputs!$B$7)^(D$2-1) -> 1525 | E12: =Units!$E11*(1+Inputs!$B$7)^(E$2-1) -> 1525 | F12: =Units!$E11*(1+Inputs!$B$7)^(F$2-1) -> 1525 | G12: =Units!$E11*(1+Inputs!$B$7)^(G$2-1) -> 1525 | H12: =Units!$E11*(1+Inputs!$B$7)^(H$2-1) -> 1525 | I12: =Units!$E11*(1+Inputs!$B$7)^(I$2-1) -> 1525 | J12: =Units!$E11*(1+Inputs!$B$7)^(J$2-1) -> 1525 | ... ED12: =Units!$E11*(1+Inputs!$B$7)^(ED$2-1) -> 2049.4725
A13: =Units!A12 -> 111 | C13: =Units!$E12*(1+Inputs!$B$7)^(C$2-1) -> 1525 | D13: =Units!$E12*(1+Inputs!$B$7)^(D$2-1) -> 1525 | E13: =Units!$E12*(1+Inputs!$B$7)^(E$2-1) -> 1525 | F13: =Units!$E12*(1+Inputs!$B$7)^(F$2-1) -> 1525 | G13: =Units!$E12*(1+Inputs!$B$7)^(G$2-1) -> 1525 | H13: =Units!$E12*(1+Inputs!$B$7)^(H$2-1) -> 1525 | I13: =Units!$E12*(1+Inputs!$B$7)^(I$2-1) -> 1525 | J13: =Units!$E12*(1+Inputs!$B$7)^(J$2-1) -> 1525 | ... ED13: =Units!$E12*(1+Inputs!$B$7)^(ED$2-1) -> 2049.4725
A14: =Units!A13 -> 112 | C14: =Units!$E13*(1+Inputs!$B$7)^(C$2-1) -> 1525 | D14: =Units!$E13*(1+Inputs!$B$7)^(D$2-1) -> 1525 | E14: =Units!$E13*(1+Inputs!$B$7)^(E$2-1) -> 1525 | F14: =Units!$E13*(1+Inputs!$B$7)^(F$2-1) -> 1525 | G14: =Units!$E13*(1+Inputs!$B$7)^(G$2-1) -> 1525 | H14: =Units!$E13*(1+Inputs!$B$7)^(H$2-1) -> 1525 | I14: =Units!$E13*(1+Inputs!$B$7)^(I$2-1) -> 1525 | J14: =Units!$E13*(1+Inputs!$B$7)^(J$2-1) -> 1525 | ... ED14: =Units!$E13*(1+Inputs!$B$7)^(ED$2-1) -> 2049.4725
... A122: =Units!A121 -> 430 | C122: =Units!$E121*(1+Inputs!$B$7)^(C$2-1) -> 2240 | D122: =Units!$E121*(1+Inputs!$B$7)^(D$2-1) -> 2240 | E122: =Units!$E121*(1+Inputs!$B$7)^(E$2-1) -> 2240 | F122: =Units!$E121*(1+Inputs!$B$7)^(F$2-1) -> 2240 | G122: =Units!$E121*(1+Inputs!$B$7)^(G$2-1) -> 2240 | H122: =Units!$E121*(1+Inputs!$B$7)^(H$2-1) -> 2240 | I122: =Units!$E121*(1+Inputs!$B$7)^(I$2-1) -> 2240 | J122: =Units!$E121*(1+Inputs!$B$7)^(J$2-1) -> 2240 | ... ED122: =Units!$E121*(1+Inputs!$B$7)^(ED$2-1) -> 3010.3727

Sheet Rent
A1: Month | B1: Opening rent | C1: 1 | D1: 2 | E1: 3 | F1: 4 | G1: 5 | H1: 6 | I1: 7 | J1: 8 | K1: 9 | L1: 10 | M1: 11 | N1: 12 | O1: 13 | P1: 14 | Q1: 15 | R1: 16 | S1: 17 | T1: 18 | U1: 19 | V1: 20 | W1: 21 | X1: 22 | Y1: 23 | Z1: 24 | AA1: 25 | AB1: 26 | AC1: 27 | AD1: 28 | AE1: 29 | AF1: 30 | AG1: 31 | AH1: 32 | AI1: 33 | AJ1: 34 | AK1: 35 | AL1: 36 | AM1: 37 | AN1: 38 | AO1: 39 | AP1: 40 | AQ1: 41 | AR1: 42 | AS1: 43 | AT1: 44 | AU1: 45 | AV1: 46 | AW1: 47 | AX1: 48 | AY1: 49 | AZ1: 50 | BA1: 51 | BB1: 52 | BC1: 53 | BD1: 54 | BE1: 55 | BF1: 56 | BG1: 57 | BH1: 58 | BI1: 59 | BJ1: 60 | BK1: 61 | BL1: 62 | BM1: 63 | BN1: 64 | BO1: 65 | BP1: 66 | BQ1: 67 | BR1: 68 | BS1: 69 | BT1: 70 | BU1: 71 | BV1: 72 | BW1: 73 | BX1: 74 | BY1: 75 | BZ1: 76 | CA1: 77 | CB1: 78 | CC1: 79 | CD1: 80 | CE1: 81 | CF1: 82 | CG1: 83 | CH1: 84 | CI1: 85 | CJ1: 86 | CK1: 87 | CL1: 88 | CM1: 89 | CN1: 90 | CO1: 91 | CP1: 92 | CQ1: 93 | CR1: 94 | CS1: 95 | CT1: 96 | CU1: 97 | CV1: 98 | CW1: 99 | CX1: 100 | CY1: 101 | CZ1: 102 | DA1: 103 | DB1: 104 | DC1: 105 | DD1: 106 | DE1: 107 | DF1: 108 | DG1: 109 | DH1: 110 | DI1: 111 | DJ1: 112 | DK1: 113 | DL1: 114 | DM1: 115 | DN1: 116 | DO1: 117 | DP1: 118 | DQ1: 119 | DR1: 120 | DS1: 121 | DT1: 122 | DU1: 123 | DV1: 124 | DW1: 125 | DX1: 126 | DY1: 127 | DZ1: 128 | EA1: 129 | EB1: 130 | EC1: 131 | ED1: 132
A2: Year | C2: =ROUNDUP(C1/12,0) -> 1 | D2: =ROUNDUP(D1/12,0) -> 1 | E2: =ROUNDUP(E1/12,0) -> 1 | F2: =ROUNDUP(F1/12,0) -> 1 | G2: =ROUNDUP(G1/12,0) -> 1 | H2: =ROUNDUP(H1/12,0) -> 1 | I2: =ROUNDUP(I1/12,0) -> 1 | J2: =ROUNDUP(J1/12,0) -> 1 | ... ED2: =ROUNDUP(ED1/12,0) -> 11
A3: =Units!A2 -> 101 | B3: =IF(Units!K2=1,Units!F2,0) -> 1565 | C3: =IF(C$1<Units!$P2,0,IF(AND(Units!$K2=0,C$1=Units!$O2),Units!$R2,IF(AND(C$1>=Units!$Q2,MOD(C$1-Units!$Q2,12)=0),IF(AND(Units!$L2=1,C$1=Units!$Q2),IF(Units!$J2<>"",Units!$J2,Mkt!C3),Inputs!$B$15*Mkt!C3+(1-Inputs!$B$15)*MIN(Mkt!C3,B3*(1+Inputs!$B$18))),B3))) -> 1565 | D3: =IF(D$1<Units!$P2,0,IF(AND(Units!$K2=0,D$1=Units!$O2),Units!$R2,IF(AND(D$1>=Units!$Q2,MOD(D$1-Units!$Q2,12)=0),IF(AND(Units!$L2=1,D$1=Units!$Q2),IF(Units!$J2<>"",Units!$J2,Mkt!D3),Inputs!$B$15*Mkt!D3+(1-Inputs!$B$15)*MIN(Mkt!D3,C3*(1+Inputs!$B$18))),C3))) -> 1525 | E3: =IF(E$1<Units!$P2,0,IF(AND(Units!$K2=0,E$1=Units!$O2),Units!$R2,IF(AND(E$1>=Units!$Q2,MOD(E$1-Units!$Q2,12)=0),IF(AND(Units!$L2=1,E$1=Units!$Q2),IF(Units!$J2<>"",Units!$J2,Mkt!E3),Inputs!$B$15*Mkt!E3+(1-Inputs!$B$15)*MIN(Mkt!E3,D3*(1+Inputs!$B$18))),D3))) -> 1525 | F3: =IF(F$1<Units!$P2,0,IF(AND(Units!$K2=0,F$1=Units!$O2),Units!$R2,IF(AND(F$1>=Units!$Q2,MOD(F$1-Units!$Q2,12)=0),IF(AND(Units!$L2=1,F$1=Units!$Q2),IF(Units!$J2<>"",Units!$J2,Mkt!F3),Inputs!$B$15*Mkt!F3+(1-Inputs!$B$15)*MIN(Mkt!F3,E3*(1+Inputs!$B$18))),E3))) -> 1525 | G3: =IF(G$1<Units!$P2,0,IF(AND(Units!$K2=0,G$1=Units!$O2),Units!$R2,IF(AND(G$1>=Units!$Q2,MOD(G$1-Units!$Q2,12)=0),IF(AND(Units!$L2=1,G$1=Units!$Q2),IF(Units!$J2<>"",Units!$J2,Mkt!G3),Inputs!$B$15*Mkt!G3+(1-Inputs!$B$15)*MIN(Mkt!G3,F3*(1+Inputs!$B$18))),F3))) -> 1525 | H3: =IF(H$1<Units!$P2,0,IF(AND(Units!$K2=0,H$1=Units!$O2),Units!$R2,IF(AND(H$1>=Units!$Q2,MOD(H$1-Units!$Q2,12)=0),IF(AND(Units!$L2=1,H$1=Units!$Q2),IF(Units!$J2<>"",Units!$J2,Mkt!H3),Inputs!$B$15*Mkt!H3+(1-Inputs!$B$15)*MIN(Mkt!H3,G3*(1+Inputs!$B$18))),G3))) -> 1525 | I3: =IF(I$1<Units!$P2,0,IF(AND(Units!$K2=0,I$1=Units!$O2),Units!$R2,IF(AND(I$1>=Units!$Q2,MOD(I$1-Units!$Q2,12)=0),IF(AND(Units!$L2=1,I$1=Units!$Q2),IF(Units!$J2<>"",Units!$J2,Mkt!I3),Inputs!$B$15*Mkt!I3+(1-Inputs!$B$15)*MIN(Mkt!I3,H3*(1+Inputs!$B$18))),H3))) -> 1525 | J3: =IF(J$1<Units!$P2,0,IF(AND(Units!$K2=0,J$1=Units!$O2),Units!$R2,IF(AND(J$1>=Units!$Q2,MOD(J$1-Units!$Q2,12)=0),IF(AND(Units!$L2=1,J$1=Units!$Q2),IF(Units!$J2<>"",Units!$J2,Mkt!J3),Inputs!$B$15*Mkt!J3+(1-Inputs!$B$15)*MIN(Mkt!J3,I3*(1+Inputs!$B$18))),I3))) -> 1525 | ... ED3: =IF(ED$1<Units!$P2,0,IF(AND(Units!$K2=0,ED$1=Units!$O2),Units!$R2,IF(AND(ED$1>=Units!$Q2,MOD(ED$1-Units!$Q2,12)=0),IF(AND(Units!$L2=1,ED$1=Units!$Q2),IF(Units!$J2<>"",Units!$J2,Mkt!ED3),Inputs!$B$15*Mkt!ED3+(1-Inputs!$B$15)*MIN(Mkt!ED3,EC3*(1+Inputs!$B$18))),EC3))) -> 2049.4725
A4: =Units!A3 -> 102 | B4: =IF(Units!K3=1,Units!F3,0) -> 1235 | C4: =IF(C$1<Units!$P3,0,IF(AND(Units!$K3=0,C$1=Units!$O3),Units!$R3,IF(AND(C$1>=Units!$Q3,MOD(C$1-Units!$Q3,12)=0),IF(AND(Units!$L3=1,C$1=Units!$Q3),IF(Units!$J3<>"",Units!$J3,Mkt!C4),Inputs!$B$15*Mkt!C4+(1-Inputs!$B$15)*MIN(Mkt!C4,B4*(1+Inputs!$B$18))),B4))) -> 1235 | D4: =IF(D$1<Units!$P3,0,IF(AND(Units!$K3=0,D$1=Units!$O3),Units!$R3,IF(AND(D$1>=Units!$Q3,MOD(D$1-Units!$Q3,12)=0),IF(AND(Units!$L3=1,D$1=Units!$Q3),IF(Units!$J3<>"",Units!$J3,Mkt!D4),Inputs!$B$15*Mkt!D4+(1-Inputs!$B$15)*MIN(Mkt!D4,C4*(1+Inputs!$B$18))),C4))) -> 1235 | E4: =IF(E$1<Units!$P3,0,IF(AND(Units!$K3=0,E$1=Units!$O3),Units!$R3,IF(AND(E$1>=Units!$Q3,MOD(E$1-Units!$Q3,12)=0),IF(AND(Units!$L3=1,E$1=Units!$Q3),IF(Units!$J3<>"",Units!$J3,Mkt!E4),Inputs!$B$15*Mkt!E4+(1-Inputs!$B$15)*MIN(Mkt!E4,D4*(1+Inputs!$B$18))),D4))) -> 1235 | F4: =IF(F$1<Units!$P3,0,IF(AND(Units!$K3=0,F$1=Units!$O3),Units!$R3,IF(AND(F$1>=Units!$Q3,MOD(F$1-Units!$Q3,12)=0),IF(AND(Units!$L3=1,F$1=Units!$Q3),IF(Units!$J3<>"",Units!$J3,Mkt!F4),Inputs!$B$15*Mkt!F4+(1-Inputs!$B$15)*MIN(Mkt!F4,E4*(1+Inputs!$B$18))),E4))) -> 1235 | G4: =IF(G$1<Units!$P3,0,IF(AND(Units!$K3=0,G$1=Units!$O3),Units!$R3,IF(AND(G$1>=Units!$Q3,MOD(G$1-Units!$Q3,12)=0),IF(AND(Units!$L3=1,G$1=Units!$Q3),IF(Units!$J3<>"",Units!$J3,Mkt!G4),Inputs!$B$15*Mkt!G4+(1-Inputs!$B$15)*MIN(Mkt!G4,F4*(1+Inputs!$B$18))),F4))) -> 1235 | H4: =IF(H$1<Units!$P3,0,IF(AND(Units!$K3=0,H$1=Units!$O3),Units!$R3,IF(AND(H$1>=Units!$Q3,MOD(H$1-Units!$Q3,12)=0),IF(AND(Units!$L3=1,H$1=Units!$Q3),IF(Units!$J3<>"",Units!$J3,Mkt!H4),Inputs!$B$15*Mkt!H4+(1-Inputs!$B$15)*MIN(Mkt!H4,G4*(1+Inputs!$B$18))),G4))) -> 1410.875 | I4: =IF(I$1<Units!$P3,0,IF(AND(Units!$K3=0,I$1=Units!$O3),Units!$R3,IF(AND(I$1>=Units!$Q3,MOD(I$1-Units!$Q3,12)=0),IF(AND(Units!$L3=1,I$1=Units!$Q3),IF(Units!$J3<>"",Units!$J3,Mkt!I4),Inputs!$B$15*Mkt!I4+(1-Inputs!$B$15)*MIN(Mkt!I4,H4*(1+Inputs!$B$18))),H4))) -> 1410.875 | J4: =IF(J$1<Units!$P3,0,IF(AND(Units!$K3=0,J$1=Units!$O3),Units!$R3,IF(AND(J$1>=Units!$Q3,MOD(J$1-Units!$Q3,12)=0),IF(AND(Units!$L3=1,J$1=Units!$Q3),IF(Units!$J3<>"",Units!$J3,Mkt!J4),Inputs!$B$15*Mkt!J4+(1-Inputs!$B$15)*MIN(Mkt!J4,I4*(1+Inputs!$B$18))),I4))) -> 1410.875 | ... ED4: =IF(ED$1<Units!$P3,0,IF(AND(Units!$K3=0,ED$1=Units!$O3),Units!$R3,IF(AND(ED$1>=Units!$Q3,MOD(ED$1-Units!$Q3,12)=0),IF(AND(Units!$L3=1,ED$1=Units!$Q3),IF(Units!$J3<>"",Units!$J3,Mkt!ED4),Inputs!$B$15*Mkt!ED4+(1-Inputs!$B$15)*MIN(Mkt!ED4,EC4*(1+Inputs!$B$18))),EC4))) -> 2049.4725
A5: =Units!A4 -> 103 | B5: =IF(Units!K4=1,Units!F4,0) -> 1475 | C5: =IF(C$1<Units!$P4,0,IF(AND(Units!$K4=0,C$1=Units!$O4),Units!$R4,IF(AND(C$1>=Units!$Q4,MOD(C$1-Units!$Q4,12)=0),IF(AND(Units!$L4=1,C$1=Units!$Q4),IF(Units!$J4<>"",Units!$J4,Mkt!C5),Inputs!$B$15*Mkt!C5+(1-Inputs!$B$15)*MIN(Mkt!C5,B5*(1+Inputs!$B$18))),B5))) -> 1475 | D5: =IF(D$1<Units!$P4,0,IF(AND(Units!$K4=0,D$1=Units!$O4),Units!$R4,IF(AND(D$1>=Units!$Q4,MOD(D$1-Units!$Q4,12)=0),IF(AND(Units!$L4=1,D$1=Units!$Q4),IF(Units!$J4<>"",Units!$J4,Mkt!D5),Inputs!$B$15*Mkt!D5+(1-Inputs!$B$15)*MIN(Mkt!D5,C5*(1+Inputs!$B$18))),C5))) -> 1475 | E5: =IF(E$1<Units!$P4,0,IF(AND(Units!$K4=0,E$1=Units!$O4),Units!$R4,IF(AND(E$1>=Units!$Q4,MOD(E$1-Units!$Q4,12)=0),IF(AND(Units!$L4=1,E$1=Units!$Q4),IF(Units!$J4<>"",Units!$J4,Mkt!E5),Inputs!$B$15*Mkt!E5+(1-Inputs!$B$15)*MIN(Mkt!E5,D5*(1+Inputs!$B$18))),D5))) -> 1475 | F5: =IF(F$1<Units!$P4,0,IF(AND(Units!$K4=0,F$1=Units!$O4),Units!$R4,IF(AND(F$1>=Units!$Q4,MOD(F$1-Units!$Q4,12)=0),IF(AND(Units!$L4=1,F$1=Units!$Q4),IF(Units!$J4<>"",Units!$J4,Mkt!F5),Inputs!$B$15*Mkt!F5+(1-Inputs!$B$15)*MIN(Mkt!F5,E5*(1+Inputs!$B$18))),E5))) -> 1475 | G5: =IF(G$1<Units!$P4,0,IF(AND(Units!$K4=0,G$1=Units!$O4),Units!$R4,IF(AND(G$1>=Units!$Q4,MOD(G$1-Units!$Q4,12)=0),IF(AND(Units!$L4=1,G$1=Units!$Q4),IF(Units!$J4<>"",Units!$J4,Mkt!G5),Inputs!$B$15*Mkt!G5+(1-Inputs!$B$15)*MIN(Mkt!G5,F5*(1+Inputs!$B$18))),F5))) -> 1475 | H5: =IF(H$1<Units!$P4,0,IF(AND(Units!$K4=0,H$1=Units!$O4),Units!$R4,IF(AND(H$1>=Units!$Q4,MOD(H$1-Units!$Q4,12)=0),IF(AND(Units!$L4=1,H$1=Units!$Q4),IF(Units!$J4<>"",Units!$J4,Mkt!H5),Inputs!$B$15*Mkt!H5+(1-Inputs!$B$15)*MIN(Mkt!H5,G5*(1+Inputs!$B$18))),G5))) -> 1475 | I5: =IF(I$1<Units!$P4,0,IF(AND(Units!$K4=0,I$1=Units!$O4),Units!$R4,IF(AND(I$1>=Units!$Q4,MOD(I$1-Units!$Q4,12)=0),IF(AND(Units!$L4=1,I$1=Units!$Q4),IF(Units!$J4<>"",Units!$J4,Mkt!I5),Inputs!$B$15*Mkt!I5+(1-Inputs!$B$15)*MIN(Mkt!I5,H5*(1+Inputs!$B$18))),H5))) -> 1475 | J5: =IF(J$1<Units!$P4,0,IF(AND(Units!$K4=0,J$1=Units!$O4),Units!$R4,IF(AND(J$1>=Units!$Q4,MOD(J$1-Units!$Q4,12)=0),IF(AND(Units!$L4=1,J$1=Units!$Q4),IF(Units!$J4<>"",Units!$J4,Mkt!J5),Inputs!$B$15*Mkt!J5+(1-Inputs!$B$15)*MIN(Mkt!J5,I5*(1+Inputs!$B$18))),I5))) -> 1475 | ... ED5: =IF(ED$1<Units!$P4,0,IF(AND(Units!$K4=0,ED$1=Units!$O4),Units!$R4,IF(AND(ED$1>=Units!$Q4,MOD(ED$1-Units!$Q4,12)=0),IF(AND(Units!$L4=1,ED$1=Units!$Q4),IF(Units!$J4<>"",Units!$J4,Mkt!ED5),Inputs!$B$15*Mkt!ED5+(1-Inputs!$B$15)*MIN(Mkt!ED5,EC5*(1+Inputs!$B$18))),EC5))) -> 2049.4725
A6: =Units!A5 -> 104 | B6: =IF(Units!K5=1,Units!F5,0) -> 0 | C6: =IF(C$1<Units!$P5,0,IF(AND(Units!$K5=0,C$1=Units!$O5),Units!$R5,IF(AND(C$1>=Units!$Q5,MOD(C$1-Units!$Q5,12)=0),IF(AND(Units!$L5=1,C$1=Units!$Q5),IF(Units!$J5<>"",Units!$J5,Mkt!C6),Inputs!$B$15*Mkt!C6+(1-Inputs!$B$15)*MIN(Mkt!C6,B6*(1+Inputs!$B$18))),B6))) -> 1525 | D6: =IF(D$1<Units!$P5,0,IF(AND(Units!$K5=0,D$1=Units!$O5),Units!$R5,IF(AND(D$1>=Units!$Q5,MOD(D$1-Units!$Q5,12)=0),IF(AND(Units!$L5=1,D$1=Units!$Q5),IF(Units!$J5<>"",Units!$J5,Mkt!D6),Inputs!$B$15*Mkt!D6+(1-Inputs!$B$15)*MIN(Mkt!D6,C6*(1+Inputs!$B$18))),C6))) -> 1525 | E6: =IF(E$1<Units!$P5,0,IF(AND(Units!$K5=0,E$1=Units!$O5),Units!$R5,IF(AND(E$1>=Units!$Q5,MOD(E$1-Units!$Q5,12)=0),IF(AND(Units!$L5=1,E$1=Units!$Q5),IF(Units!$J5<>"",Units!$J5,Mkt!E6),Inputs!$B$15*Mkt!E6+(1-Inputs!$B$15)*MIN(Mkt!E6,D6*(1+Inputs!$B$18))),D6))) -> 1525 | F6: =IF(F$1<Units!$P5,0,IF(AND(Units!$K5=0,F$1=Units!$O5),Units!$R5,IF(AND(F$1>=Units!$Q5,MOD(F$1-Units!$Q5,12)=0),IF(AND(Units!$L5=1,F$1=Units!$Q5),IF(Units!$J5<>"",Units!$J5,Mkt!F6),Inputs!$B$15*Mkt!F6+(1-Inputs!$B$15)*MIN(Mkt!F6,E6*(1+Inputs!$B$18))),E6))) -> 1525 | G6: =IF(G$1<Units!$P5,0,IF(AND(Units!$K5=0,G$1=Units!$O5),Units!$R5,IF(AND(G$1>=Units!$Q5,MOD(G$1-Units!$Q5,12)=0),IF(AND(Units!$L5=1,G$1=Units!$Q5),IF(Units!$J5<>"",Units!$J5,Mkt!G6),Inputs!$B$15*Mkt!G6+(1-Inputs!$B$15)*MIN(Mkt!G6,F6*(1+Inputs!$B$18))),F6))) -> 1525 | H6: =IF(H$1<Units!$P5,0,IF(AND(Units!$K5=0,H$1=Units!$O5),Units!$R5,IF(AND(H$1>=Units!$Q5,MOD(H$1-Units!$Q5,12)=0),IF(AND(Units!$L5=1,H$1=Units!$Q5),IF(Units!$J5<>"",Units!$J5,Mkt!H6),Inputs!$B$15*Mkt!H6+(1-Inputs!$B$15)*MIN(Mkt!H6,G6*(1+Inputs!$B$18))),G6))) -> 1525 | I6: =IF(I$1<Units!$P5,0,IF(AND(Units!$K5=0,I$1=Units!$O5),Units!$R5,IF(AND(I$1>=Units!$Q5,MOD(I$1-Units!$Q5,12)=0),IF(AND(Units!$L5=1,I$1=Units!$Q5),IF(Units!$J5<>"",Units!$J5,Mkt!I6),Inputs!$B$15*Mkt!I6+(1-Inputs!$B$15)*MIN(Mkt!I6,H6*(1+Inputs!$B$18))),H6))) -> 1525 | J6: =IF(J$1<Units!$P5,0,IF(AND(Units!$K5=0,J$1=Units!$O5),Units!$R5,IF(AND(J$1>=Units!$Q5,MOD(J$1-Units!$Q5,12)=0),IF(AND(Units!$L5=1,J$1=Units!$Q5),IF(Units!$J5<>"",Units!$J5,Mkt!J6),Inputs!$B$15*Mkt!J6+(1-Inputs!$B$15)*MIN(Mkt!J6,I6*(1+Inputs!$B$18))),I6))) -> 1525 | ... ED6: =IF(ED$1<Units!$P5,0,IF(AND(Units!$K5=0,ED$1=Units!$O5),Units!$R5,IF(AND(ED$1>=Units!$Q5,MOD(ED$1-Units!$Q5,12)=0),IF(AND(Units!$L5=1,ED$1=Units!$Q5),IF(Units!$J5<>"",Units!$J5,Mkt!ED6),Inputs!$B$15*Mkt!ED6+(1-Inputs!$B$15)*MIN(Mkt!ED6,EC6*(1+Inputs!$B$18))),EC6))) -> 2049.4725
